Workbook

Sheet Rules
C1: Men | H1: Women | L1: Competition Rules
C2: PAR | D2: CR | E2: Slope | H2: PAR | I2: CR | J2: Slope
B3: Yellow | C3: 72 | D3: 79 | E3: 136 | G3: Yellow | H3: 72 | I3: 72.7 | J3: 124
B4: White | C4: 72 | D4: 71.6 | E4: 119 | G4: White | H4: 72 | I4: 77.7 | J4: 137
B5: Blue | C5: 72 | D5: 68.7 | E5: 116 | G5: Blue | H5: 72 | I5: 75 | J5: 130
B6: Red | C6: 72 | D6: 67 | E6: 111 | G6: Red | H6: 72 | I6: 72.7 | J6: 123
L8: Women | P8: Eclectic % of Handicap to Use
C9: Div A | H9: GOLD | L9: Div A | P9: 25
C10: HI Range | D10: -100 | E10: 6 | H10: HI Range | I10: -999 | J10: 6.5 | L10: HI Range | M10: =IF($L$8="Men",D10,I10) -> -999 | N10: =IF($L$8="Men",E10,J10) -> 6.5
D11: Handicap % | E11: 25 | I11: Handicap % | J11: 100 | M11: Handicap % | N11: =IF($L$8="Men",E11,J11) -> 100
C12: White | D12: Par | E12: =VLOOKUP(C12,$B$3:$E$6,2,FALSE) -> 72 | H12: Red | I12: Par | J12: =VLOOKUP(H12,$G$3:$J$6,2,FALSE) -> 72 | L12: =IF($L$8="Men",C12,H12) -> Red | M12: Par | N12: =IF($L$8="Men",E12,J12) -> 72
C13: =C12 -> White | D13: CR | E13: =VLOOKUP(C13,$B$3:$E$6,3,FALSE) -> 71.6 | H13: =H12 -> Red | I13: CR | J13: =VLOOKUP(H13,$G$3:$J$6,3,FALSE) -> 72.7 | L13: =IF($L$8="Men",C13,H13) -> Red | M13: CR | N13: =IF($L$8="Men",E13,J13) -> 72.7
C14: =C12 -> White | D14: Slope | E14: =VLOOKUP(C14,$B$3:$E$6,4,FALSE) -> 119 | H14: =H12 -> Red | I14: Slope | J14: =VLOOKUP(H14,$G$3:$J$6,4,FALSE) -> 123 | L14: =IF($L$8="Men",C14,H14) -> Red | M14: Slope | N14: =IF($L$8="Men",E14,J14) -> 123
C16: Div B | H16: SILVER | L16: Div B
C17: HI Range | D17: 6.1 | E17: 14.9 | H17: HI Range | I17: 6.6 | J17: 15.3 | L17: HI Range | M17: =IF($L$8="Men",D17,I17) -> 6.6 | N17: =IF($L$8="Men",E17,J17) -> 15.3
D18: Handicap % | E18: 100 | I18: Handicap % | J18: 100 | M18: Handicap % | N18: =IF($L$8="Men",E18,J18) -> 100
C19: Yellow | D19: Par | E19: =VLOOKUP(C19,$B$3:$E$6,2,FALSE) -> 72 | H19: Red | I19: Par | J19: =VLOOKUP(H19,$G$3:$J$6,2,FALSE) -> 72 | L19: =IF($L$8="Men",C19,H19) -> Red | M19: Par | N19: =IF($L$8="Men",E19,J19) -> 72
C20: =C19 -> Yellow | D20: CR | E20: =VLOOKUP(C20,$B$3:$E$6,3,FALSE) -> 79 | H20: =H19 -> Red | I20: CR | J20: =VLOOKUP(H20,$G$3:$J$6,3,FALSE) -> 72.7 | L20: =IF($L$8="Men",C20,H20) -> Red | M20: CR | N20: =IF($L$8="Men",E20,J20) -> 72.7
C21: =C19 -> Yellow | D21: Slope | E21: =VLOOKUP(C21,$B$3:$E$6,4,FALSE) -> 136 | H21: =H19 -> Red | I21: Slope | J21: =VLOOKUP(H21,$G$3:$J$6,4,FALSE) -> 123 | L21: =IF($L$8="Men",C21,H21) -> Red | M21: Slope | N21: =IF($L$8="Men",E21,J21) -> 123
C23: Div C | H23: Div C | L23: Div C
C24: HI Range | D24: 15 | E24: 1000 | H24: HI Range | I24: 15.4 | J24: 10001 | L24: HI Range | M24: =IF($L$8="Men",D24,I24) -> 15.4 | N24: =IF($L$8="Men",E24,J24) -> 10001
D25: Handicap % | E25: 100 | I25: Handicap % | J25: 100 | M25: Handicap % | N25: =IF($L$8="Men",E25,J25) -> 100
C26: Yellow | D26: Par | E26: =VLOOKUP(C26,$B$3:$E$6,2,FALSE) -> 72 | H26: Red | I26: Par | J26: =VLOOKUP(H26,$G$3:$J$6,2,FALSE) -> 72 | L26: =IF($L$8="Men",C26,H26) -> Red | M26: Par | N26: =IF($L$8="Men",E26,J26) -> 72
C27: =C26 -> Yellow | D27: CR | E27: =VLOOKUP(C27,$B$3:$E$6,3,FALSE) -> 79 | H27: =H26 -> Red | I27: CR | J27: =VLOOKUP(H27,$G$3:$J$6,3,FALSE) -> 72.7 | L27: =IF($L$8="Men",C27,H27) -> Red | M27: CR | N27: =IF($L$8="Men",E27,J27) -> 72.7
C28: =C26 -> Yellow | D28: Slope | E28: =VLOOKUP(C28,$B$3:$E$6,4,FALSE) -> 136 | H28: =H26 -> Red | I28: Slope | J28: =VLOOKUP(H28,$G$3:$J$6,4,FALSE) -> 123 | L28: =IF($L$8="Men",C28,H28) -> Red | M28: Slope | N28: =IF($L$8="Men",E28,J28) -> 123
C30: Div D | H30: Div D | L30: Div D
C31: Any Handicap - Blue Tee's | H31: Any Handicap - Blue Tee's | L31: Any Handicap - Blue Tee's
D32: Handicap % | E32: 100 | I32: Handicap % | J32: 100 | M32: Handicap % | N32: =IF($L$8="Men",E32,J32) -> 100
C33: Blue | D33: Par | E33: =VLOOKUP(C33,$B$3:$E$6,2,FALSE) -> 72 | H33: Red | I33: Par | J33: =VLOOKUP(H33,$G$3:$J$6,2,FALSE) -> 72 | L33: =IF($L$8="Men",C33,H33) -> Red | M33: Par | N33: =IF($L$8="Men",E33,J33) -> 72
C34: =C33 -> Blue | D34: CR | E34: =VLOOKUP(C34,$B$3:$E$6,3,FALSE) -> 68.7 | H34: =H33 -> Red | I34: CR | J34: =VLOOKUP(H34,$G$3:$J$6,3,FALSE) -> 72.7 | L34: =IF($L$8="Men",C34,H34) -> Red | M34: CR | N34: =IF($L$8="Men",E34,J34) -> 72.7
C35: =C33 -> Blue | D35: Slope | E35: =VLOOKUP(C35,$B$3:$E$6,4,FALSE) -> 116 | H35: =H33 -> Red | I35: Slope | J35: =VLOOKUP(H35,$G$3:$J$6,4,FALSE) -> 123 | L35: =IF($L$8="Men",C35,H35) -> Red | M35: Slope | N35: =IF($L$8="Men",E35,J35) -> 123
L37: Max Handicap | N37: 36

Sheet Players
A1: A Division | F1: B Division | K1: C Division
A2: First Name | B2: Last Name | C2: SA ID | D2: HI | F2: First Name | G2: Last Name | H2: SA ID | I2: HI | K2: First Name | L2: Last Name | M2: SA ID | N2: HI
A3: KAY | B3: DUNKLEY | C3: 2700149294 | D3: 14.2 | F3: KAY | G3: DUNKLEY | H3: 2700149294 | I3: 14.2 | K3: SHAY | L3: BROEDELET | M3: 2700181092 | N3: 25.4
A4: ALIDA | B4: HOOPER | C4: 2700180851 | D4: 13.4 | F4: ALIDA | G4: HOOPER | H4: 2700180851 | I4: 13.4 | K4: PREM | L4: GOVENDER | M4: 2700181058 | N4: 23.7
A5: SONJA | B5: HOPCROFT | C5: 2700333319 | D5: 11.4 | F5: SONJA | G5: HOPCROFT | H5: 2700333319 | I5: 11.4 | K5: RENE | L5: LADELL | M5: 2700093097 | N5: 33
A6: TARA | B6: SMITH | C6: 2700438384 | D6: 1 | F6: TARA | G6: SMITH | H6: 2700438384 | I6: 1 | K6: ANGELA | L6: MASEFIELD | M6: 2700191557 | N6: 19.5
A7: ANITA | B7: VAN DER LINDE | C7: 2700227060 | D7: 13.9 | F7: ANITA | G7: VAN DER LINDE | H7: 2700227060 | I7: 13.9 | K7: FIFI | L7: NARAN | M7: 2700110837 | N7: 22.5
A8: SHAY | B8: BROEDELET | C8: 2700181092 | D8: 25.4 | K8: JANIS | L8: NEL | M8: 2700223146 | N8: 18
A9: PREM | B9: GOVENDER | C9: 2700181058 | D9: 23.7 | K9: MELISSA | L9: PALMER | M9: 2700307743 | N9: 17.9
A10: RENE | B10: LADELL | C10: 2700093097 | D10: 33 | K10: MELISSA | L10: SAVIO | M10: 2700290517 | N10: 23.9
A11: ANGELA | B11: MASEFIELD | C11: 2700191557 | D11: 19.5 | K11: GAIL | L11: SPEIRS | M11: 2700179246 | N11: 17.6
A12: FIFI | B12: NARAN | C12: 2700110837 | D12: 22.5 | K12: KAREN | L12: STOTT | M12: 2700116107 | N12: 17.6
A13: JANIS | B13: NEL | C13: 2700223146 | D13: 18 | K13: JUDY | L13: VAN DER VEEN | M13: 2700269173 | N13: 19.8
A14: MELISSA | B14: PALMER | C14: 2700307743 | D14: 17.9
A15: MELISSA | B15: SAVIO | C15: 2700290517 | D15: 23.9
A16: GAIL | B16: SPEIRS | C16: 2700179246 | D16: 17.6
A17: KAREN | B17: STOTT | C17: 2700116107 | D17: 17.6
A18: JUDY | B18: VAN DER VEEN | C18: 2700269173 | D18: 19.8

Sheet Eclectic A
CD2: Gross of best for each day less 25% of Playing Handicap
D3: DAY 1 | AA3: DAY 2 | AX3: Eclectic | CD3: A Div - Eclectic
A4: # | B4: Name | C4: HC | D4: 1 | E4: 2 | F4: 3 | G4: 4 | H4: 5 | I4: 6 | J4: 7 | K4: 8 | L4: 9 | M4: OUT | N4: 10 | O4: 11 | P4: 12 | Q4: 13 | R4: 14 | S4: 15 | T4: 16 | U4: 17 | V4: 18 | W4: IN | X4: GROSS | Y4: NET | AA4: 1 | AB4: 2 | AC4: 3 | AD4: 4 | AE4: 5 | AF4: 6 | AG4: 7 | AH4: 8 | AI4: 9 | AJ4: OUT | AK4: 10 | AL4: 11 | AM4: 12 | AN4: 13 | AO4: 14 | AP4: 15 | AQ4: 16 | AR4: 17 | AS4: 18 | AT4: IN | AU4: GROSS | AV4: NET | AX4: 1 | AY4: 2 | AZ4: 3 | BA4: 4 | BB4: 5 | BC4: 6 | BD4: 7 | BE4: 8 | BF4: 9 | BG4: OUT | BH4: 10 | BI4: 11 | BJ4: 12 | BK4: 13 | BL4: 14 | BM4: 15 | BN4: 16 | BO4: 17 | BP4: 18 | BQ4: IN | BR4: OUT | BS4: Gross | BT4: Net | BU4: Net RANK (no ties) | BV4: Net Rank with Ties | BW4: Name And Surname | BX4: HC | BY4: Net | CD4: Pos | CE4: Name | CF4: Net
A5: 1 | B5: ='A Div'!A5 & " " & 'A Div'!B5 -> KAY DUNKLEY | C5: ='A Div'!E5 -> 16 | D5: 6 | E5: 5 | F5: 6 | G5: 6 | H5: 5 | I5: 3 | J5: 6 | K5: 5 | L5: 5 | M5: =IF(COUNTIF(D5:L5,"<>"&"")=9,SUM(D5:L5),"-") -> 47 | N5: 7 | O5: 4 | P5: 4 | Q5: 4 | R5: 4 | S5: 5 | T5: 4 | U5: 5 | V5: 7 | W5: =IF(COUNTIF(N5:V5,"<>"&"")=9,SUM(N5:V5),"-") -> 44 | X5: =IF(AND(ISNUMBER(M5),ISNUMBER(W5)),M5+W5,"-") -> 91 | Y5: =IF(ISNUMBER(X5),X5-C5,"-") -> 75 | AA5: 5 | AB5: 4 | AC5: 5 | AD5: 5 | AE5: 7 | AF5: 4 | AG5: 5 | AH5: 5 | AI5: 5 | AJ5: =IF(COUNTIF(AA5:AI5,"<>"&"")=9,SUM(AA5:AI5),"-") -> 45 | AK5: 6 | AL5: 8 | AM5: 3 | AN5: 6 | AO5: 4 | AP5: 6 | AQ5: 4 | AR5: 6 | AS5: 7 | AT5: =IF(COUNTIF(AK5:AS5,"<>"&"")=9,SUM(AK5:AS5),"-") -> 50 | AU5: =IF(AND(ISNUMBER(AJ5),ISNUMBER(AT5)),AJ5+AT5,"-") -> 95 | AV5: =IF(ISNUMBER(AU5),AU5-C5,"-") -> 79 | AX5: =IF(AND(D5>0,AA5>0),MIN(D5,AA5),"-") -> 5 | AY5: =IF(AND(E5>0,AB5>0),MIN(E5,AB5),"-") -> 4 | AZ5: =IF(AND(F5>0,AC5>0),MIN(F5,AC5),"-") -> 5 | BA5: =IF(AND(G5>0,AD5>0),MIN(G5,AD5),"-") -> 5 | BB5: =IF(AND(H5>0,AE5>0),MIN(H5,AE5),"-") -> 5 | BC5: =IF(AND(I5>0,AF5>0),MIN(I5,AF5),"-") -> 3 | BD5: =IF(AND(J5>0,AG5>0),MIN(J5,AG5),"-") -> 5 | BE5: =IF(AND(K5>0,AH5>0),MIN(K5,AH5),"-") -> 5 | BF5: =IF(AND(L5>0,AI5>0),MIN(L5,AI5),"-") -> 5 | BG5: =IF(COUNTIF(AX5:BF5,"<>-")=9,SUM(AX5:BF5),"-") -> 42 | BH5: =IF(AND(N5>0,AK5>0),MIN(N5,AK5),"-") -> 6 | BI5: =IF(AND(O5>0,AL5>0),MIN(O5,AL5),"-") -> 4 | BJ5: =IF(AND(P5>0,AM5>0),MIN(P5,AM5),"-") -> 3 | BK5: =IF(AND(Q5>0,AN5>0),MIN(Q5,AN5),"-") -> 4 | BL5: =IF(AND(R5>0,AO5>0),MIN(R5,AO5),"-") -> 4 | BM5: =IF(AND(S5>0,AP5>0),MIN(S5,AP5),"-") -> 5 | BN5: =IF(AND(T5>0,AQ5>0),MIN(T5,AQ5),"-") -> 4 | BO5: =IF(AND(U5>0,AR5>0),MIN(U5,AR5),"-") -> 5 | BP5: =IF(AND(V5>0,AS5>0),MIN(V5,AS5),"-") -> 7 | BQ5: =IF(COUNTIF(BH5:BP5,"<>-")=9,SUM(BH5:BP5),"-") -> 42 | BR5: =BG5 -> 42 | BS5: =IF(COUNTIF(BQ5:BR5,"<>-")=2,SUM(BQ5:BR5),"-") -> 84 | BT5: =IF(ISNUMBER(BS5),BS5-(C5*Rules!$P$9/100),"-") -> 80 | BU5: =RANK($BT5,$BT$5:$BT$106,1)+COUNTIF(BT$5:BT5,BT5)-1 -> 4 | BV5: =RANK(BT5,$BT$5:$BT$215,1) -> 4 | BW5: =B5 -> KAY DUNKLEY | BX5: =C5 -> 16 | BY5: =BT5 -> 80 | CC5: 1 | CD5: =VLOOKUP(CC5,$BU$5:BY$215,2,FALSE) -> 1 | CE5: =VLOOKUP(CC5,$BU$5:BY$215,3,FALSE) -> TARA SMITH | CF5: =VLOOKUP(CC5,$BU$5:BY$215,5,FALSE) -> 70.5 | CL5: 1
A6: 2 | B6: ='A Div'!A6 & " " & 'A Div'!B6 -> ALIDA HOOPER | C6: ='A Div'!E6 -> 15 | D6: 5 | E6: 3 | F6: 6 | G6: 4 | H6: 5 | I6: 4 | J6: 4 | K6: 6 | L6: 5 | M6: =IF(COUNTIF(D6:L6,"<>"&"")=9,SUM(D6:L6),"-") -> 42 | N6: 6 | O6: 6 | P6: 6 | Q6: 8 | R6: 3 | S6: 6 | T6: 6 | U6: 7 | V6: 7 | W6: =IF(COUNTIF(N6:V6,"<>"&"")=9,SUM(N6:V6),"-") -> 55 | X6: =IF(AND(ISNUMBER(M6),ISNUMBER(W6)),M6+W6,"-") -> 97 | Y6: =IF(ISNUMBER(X6),X6-C6,"-") -> 82 | AA6: 4 | AB6: 4 | AC6: 5 | AD6: 5 | AE6: 6 | AF6: 4 | AG6: 6 | AH6: 5 | AI6: 5 | AJ6: =IF(COUNTIF(AA6:AI6,"<>"&"")=9,SUM(AA6:AI6),"-") -> 44 | AK6: 5 | AL6: 5 | AM6: 6 | AN6: 6 | AO6: 4 | AP6: 5 | AQ6: 4 | AR6: 6 | AS6: 6 | AT6: =IF(COUNTIF(AK6:AS6,"<>"&"")=9,SUM(AK6:AS6),"-") -> 47 | AU6: =IF(AND(ISNUMBER(AJ6),ISNUMBER(AT6)),AJ6+AT6,"-") -> 91 | AV6: =IF(ISNUMBER(AU6),AU6-C6,"-") -> 76 | AX6: =IF(AND(D6>0,AA6>0),MIN(D6,AA6),"-") -> 4 | AY6: =IF(AND(E6>0,AB6>0),MIN(E6,AB6),"-") -> 3 | AZ6: =IF(AND(F6>0,AC6>0),MIN(F6,AC6),"-") -> 5 | BA6: =IF(AND(G6>0,AD6>0),MIN(G6,AD6),"-") -> 4 | BB6: =IF(AND(H6>0,AE6>0),MIN(H6,AE6),"-") -> 5 | BC6: =IF(AND(I6>0,AF6>0),MIN(I6,AF6),"-") -> 4 | BD6: =IF(AND(J6>0,AG6>0),MIN(J6,AG6),"-") -> 4 | BE6: =IF(AND(K6>0,AH6>0),MIN(K6,AH6),"-") -> 5 | BF6: =IF(AND(L6>0,AI6>0),MIN(L6,AI6),"-") -> 5 | BG6: =IF(COUNTIF(AX6:BF6,"<>-")=9,SUM(AX6:BF6),"-") -> 39 | BH6: =IF(AND(N6>0,AK6>0),MIN(N6,AK6),"-") -> 5 | BI6: =IF(AND(O6>0,AL6>0),MIN(O6,AL6),"-") -> 5 | BJ6: =IF(AND(P6>0,AM6>0),MIN(P6,AM6),"-") -> 6 | BK6: =IF(AND(Q6>0,AN6>0),MIN(Q6,AN6),"-") -> 6 | BL6: =IF(AND(R6>0,AO6>0),MIN(R6,AO6),"-") -> 3 | BM6: =IF(AND(S6>0,AP6>0),MIN(S6,AP6),"-") -> 5 | BN6: =IF(AND(T6>0,AQ6>0),MIN(T6,AQ6),"-") -> 4 | BO6: =IF(AND(U6>0,AR6>0),MIN(U6,AR6),"-") -> 6 | BP6: =IF(AND(V6>0,AS6>0),MIN(V6,AS6),"-") -> 6 | BQ6: =IF(COUNTIF(BH6:BP6,"<>-")=9,SUM(BH6:BP6),"-") -> 46 | BR6: =BG6 -> 39 | BS6: =IF(COUNTIF(BQ6:BR6,"<>-")=2,SUM(BQ6:BR6),"-") -> 85 | BT6: =IF(ISNUMBER(BS6),BS6-(C6*Rules!$P$9/100),"-") -> 81.25 | BU6: =RANK($BT6,$BT$5:$BT$106,1)+COUNTIF(BT$5:BT6,BT6)-1 -> 9 | BV6: =RANK(BT6,$BT$5:$BT$215,1) -> 9 | BW6: =B6 -> ALIDA HOOPER | BX6: =C6 -> 15 | BY6: =BT6 -> 81.25 | CC6: 2 | CD6: =VLOOKUP(CC6,$BU$5:BY$215,2,FALSE) -> 2 | CE6: =VLOOKUP(CC6,$BU$5:BY$215,3,FALSE) -> MELISSA PALMER | CF6: =VLOOKUP(CC6,$BU$5:BY$215,5,FALSE) -> 78 | CL6: 1
A7: 3 | B7: ='A Div'!A7 & " " & 'A Div'!B7 -> SONJA HOPCROFT | C7: ='A Div'!E7 -> 13 | D7: 6 | E7: 3 | F7: 6 | G7: 4 | H7: 5 | I7: 6 | J7: 6 | K7: 5 | L7: 4 | M7: =IF(COUNTIF(D7:L7,"<>"&"")=9,SUM(D7:L7),"-") -> 45 | N7: 7 | O7: 5 | P7: 4 | Q7: 6 | R7: 3 | S7: 6 | T7: 5 | U7: 5 | V7: 7 | W7: =IF(COUNTIF(N7:V7,"<>"&"")=9,SUM(N7:V7),"-") -> 48 | X7: =IF(AND(ISNUMBER(M7),ISNUMBER(W7)),M7+W7,"-") -> 93 | Y7: =IF(ISNUMBER(X7),X7-C7,"-") -> 80 | AA7: 5 | AB7: 4 | AC7: 6 | AD7: 4 | AE7: 6 | AF7: 6 | AG7: 5 | AH7: 5 | AI7: 7 | AJ7: =IF(COUNTIF(AA7:AI7,"<>"&"")=9,SUM(AA7:AI7),"-") -> 48 | AK7: 5 | AL7: 7 | AM7: 3 | AN7: 5 | AO7: 5 | AP7: 6 | AQ7: 4 | AR7: 5 | AS7: 5 | AT7: =IF(COUNTIF(AK7:AS7,"<>"&"")=9,SUM(AK7:AS7),"-") -> 45 | AU7: =IF(AND(ISNUMBER(AJ7),ISNUMBER(AT7)),AJ7+AT7,"-") -> 93 | AV7: =IF(ISNUMBER(AU7),AU7-C7,"-") -> 80 | AX7: =IF(AND(D7>0,AA7>0),MIN(D7,AA7),"-") -> 5 | AY7: =IF(AND(E7>0,AB7>0),MIN(E7,AB7),"-") -> 3 | AZ7: =IF(AND(F7>0,AC7>0),MIN(F7,AC7),"-") -> 6 | BA7: =IF(AND(G7>0,AD7>0),MIN(G7,AD7),"-") -> 4 | BB7: =IF(AND(H7>0,AE7>0),MIN(H7,AE7),"-") -> 5 | BC7: =IF(AND(I7>0,AF7>0),MIN(I7,AF7),"-") -> 6 | BD7: =IF(AND(J7>0,AG7>0),MIN(J7,AG7),"-") -> 5 | BE7: =IF(AND(K7>0,AH7>0),MIN(K7,AH7),"-") -> 5 | BF7: =IF(AND(L7>0,AI7>0),MIN(L7,AI7),"-") -> 4 | BG7: =IF(COUNTIF(AX7:BF7,"<>-")=9,SUM(AX7:BF7),"-") -> 43 | BH7: =IF(AND(N7>0,AK7>0),MIN(N7,AK7),"-") -> 5 | BI7: =IF(AND(O7>0,AL7>0),MIN(O7,AL7),"-") -> 5 | BJ7: =IF(AND(P7>0,AM7>0),MIN(P7,AM7),"-") -> 3 | BK7: =IF(AND(Q7>0,AN7>0),MIN(Q7,AN7),"-") -> 5 | BL7: =IF(AND(R7>0,AO7>0),MIN(R7,AO7),"-") -> 3 | BM7: =IF(AND(S7>0,AP7>0),MIN(S7,AP7),"-") -> 6 | BN7: =IF(AND(T7>0,AQ7>0),MIN(T7,AQ7),"-") -> 4 | BO7: =IF(AND(U7>0,AR7>0),MIN(U7,AR7),"-") -> 5 | BP7: =IF(AND(V7>0,AS7>0),MIN(V7,AS7),"-") -> 5 | BQ7: =IF(COUNTIF(BH7:BP7,"<>-")=9,SUM(BH7:BP7),"-") -> 41 | BR7: =BG7 -> 43 | BS7: =IF(COUNTIF(BQ7:BR7,"<>-")=2,SUM(BQ7:BR7),"-") -> 84 | BT7: =IF(ISNUMBER(BS7),BS7-(C7*Rules!$P$9/100),"-") -> 80.75 | BU7: =RANK($BT7,$BT$5:$BT$106,1)+COUNTIF(BT$5:BT7,BT7)-1 -> 7 | BV7: =RANK(BT7,$BT$5:$BT$215,1) -> 7 | BW7: =B7 -> SONJA HOPCROFT | BX7: =C7 -> 13 | BY7: =BT7 -> 80.75 | CC7: 3 | CD7: =VLOOKUP(CC7,$BU$5:BY$215,2,FALSE) -> 3 | CE7: =VLOOKUP(CC7,$BU$5:BY$215,3,FALSE) -> ANITA VAN DER LINDE | CF7: =VLOOKUP(CC7,$BU$5:BY$215,5,FALSE) -> 79 | CL7: 1
A8: 4 | B8: ='A Div'!A8 & " " & 'A Div'!B8 -> TARA SMITH | C8: ='A Div'!E8 -> 2 | D8: 4 | E8: 3 | F8: 4 | G8: 4 | H8: 5 | I8: 3 | J8: 4 | K8: 4 | L8: 3 | M8: =IF(COUNTIF(D8:L8,"<>"&"")=9,SUM(D8:L8),"-") -> 34 | N8: 4 | O8: 4 | P8: 3 | Q8: 4 | R8: 4 | S8: 5 | T8: 4 | U8: 5 | V8: 5 | W8: =IF(COUNTIF(N8:V8,"<>"&"")=9,SUM(N8:V8),"-") -> 38 | X8: =IF(AND(ISNUMBER(M8),ISNUMBER(W8)),M8+W8,"-") -> 72 | Y8: =IF(ISNUMBER(X8),X8-C8,"-") -> 70 | AA8: 4 | AB8: 4 | AC8: 4 | AD8: 5 | AE8: 7 | AF8: 5 | AG8: 4 | AH8: 4 | AI8: 3 | AJ8: =IF(COUNTIF(AA8:AI8,"<>"&"")=9,SUM(AA8:AI8),"-") -> 40 | AK8: 5 | AL8: 4 | AM8: 4 | AN8: 4 | AO8: 6 | AP8: 4 | AQ8: 5 | AR8: 5 | AS8: 5 | AT8: =IF(COUNTIF(AK8:AS8,"<>"&"")=9,SUM(AK8:AS8),"-") -> 42 | AU8: =IF(AND(ISNUMBER(AJ8),ISNUMBER(AT8)),AJ8+AT8,"-") -> 82 | AV8: =IF(ISNUMBER(AU8),AU8-C8,"-") -> 80 | AX8: =IF(AND(D8>0,AA8>0),MIN(D8,AA8),"-") -> 4 | AY8: =IF(AND(E8>0,AB8>0),MIN(E8,AB8),"-") -> 3 | AZ8: =IF(AND(F8>0,AC8>0),MIN(F8,AC8),"-") -> 4 | BA8: =IF(AND(G8>0,AD8>0),MIN(G8,AD8),"-") -> 4 | BB8: =IF(AND(H8>0,AE8>0),MIN(H8,AE8),"-") -> 5 | BC8: =IF(AND(I8>0,AF8>0),MIN(I8,AF8),"-") -> 3 | BD8: =IF(AND(J8>0,AG8>0),MIN(J8,AG8),"-") -> 4 | BE8: =IF(AND(K8>0,AH8>0),MIN(K8,AH8),"-") -> 4 | BF8: =IF(AND(L8>0,AI8>0),MIN(L8,AI8),"-") -> 3 | BG8: =IF(COUNTIF(AX8:BF8,"<>-")=9,SUM(AX8:BF8),"-") -> 34 | BH8: =IF(AND(N8>0,AK8>0),MIN(N8,AK8),"-") -> 4 | BI8: =IF(AND(O8>0,AL8>0),MIN(O8,AL8),"-") -> 4 | BJ8: =IF(AND(P8>0,AM8>0),MIN(P8,AM8),"-") -> 3 | BK8: =IF(AND(Q8>0,AN8>0),MIN(Q8,AN8),"-") -> 4 | BL8: =IF(AND(R8>0,AO8>0),MIN(R8,AO8),"-") -> 4 | BM8: =IF(AND(S8>0,AP8>0),MIN(S8,AP8),"-") -> 4 | BN8: =IF(AND(T8>0,AQ8>0),MIN(T8,AQ8),"-") -> 4 | BO8: =IF(AND(U8>0,AR8>0),MIN(U8,AR8),"-") -> 5 | BP8: =IF(AND(V8>0,AS8>0),MIN(V8,AS8),"-") -> 5 | BQ8: =IF(COUNTIF(BH8:BP8,"<>-")=9,SUM(BH8:BP8),"-") -> 37 | BR8: =BG8 -> 34 | BS8: =IF(COUNTIF(BQ8:BR8,"<>-")=2,SUM(BQ8:BR8),"-") -> 71 | BT8: =IF(ISNUMBER(BS8),BS8-(C8*Rules!$P$9/100),"-") -> 70.5 | BU8: =RANK($BT8,$BT$5:$BT$106,1)+COUNTIF(BT$5:BT8,BT8)-1 -> 1 | BV8: =RANK(BT8,$BT$5:$BT$215,1) -> 1 | BW8: =B8 -> TARA SMITH | BX8: =C8 -> 2 | BY8: =BT8 -> 70.5 | CC8: 4 | CD8: =VLOOKUP(CC8,$BU$5:BY$215,2,FALSE) -> 4 | CE8: =VLOOKUP(CC8,$BU$5:BY$215,3,FALSE) -> KAY DUNKLEY | CF8: =VLOOKUP(CC8,$BU$5:BY$215,5,FALSE) -> 80 | CL8: 1
A9: 5 | B9: ='A Div'!A9 & " " & 'A Div'!B9 -> ANITA VAN DER LINDE | C9: ='A Div'!E9 -> 16 | D9: 6 | E9: 3 | F9: 6 | G9: 7 | H9: 5 | I9: 3 | J9: 5 | K9: 6 | L9: 4 | M9: =IF(COUNTIF(D9:L9,"<>"&"")=9,SUM(D9:L9),"-") -> 45 | N9: 8 | O9: 4 | P9: 4 | Q9: 6 | R9: 4 | S9: 6 | T9: 3 | U9: 6 | V9: 7 | W9: =IF(COUNTIF(N9:V9,"<>"&"")=9,SUM(N9:V9),"-") -> 48 | X9: =IF(AND(ISNUMBER(M9),ISNUMBER(W9)),M9+W9,"-") -> 93 | Y9: =IF(ISNUMBER(X9),X9-C9,"-") -> 77 | AA9: 5 | AB9: 3 | AC9: 5 | AD9: 5 | AE9: 7 | AF9: 3 | AG9: 6 | AH9: 5 | AI9: 4 | AJ9: =IF(COUNTIF(AA9:AI9,"<>"&"")=9,SUM(AA9:AI9),"-") -> 43 | AK9: 7 | AL9: 4 | AM9: 3 | AN9: 6 | AO9: 3 | AP9: 6 | AQ9: 5 | AR9: 6 | AS9: 5 | AT9: =IF(COUNTIF(AK9:AS9,"<>"&"")=9,SUM(AK9:AS9),"-") -> 45 | AU9: =IF(AND(ISNUMBER(AJ9),ISNUMBER(AT9)),AJ9+AT9,"-") -> 88 | AV9: =IF(ISNUMBER(AU9),AU9-C9,"-") -> 72 | AX9: =IF(AND(D9>0,AA9>0),MIN(D9,AA9),"-") -> 5 | AY9: =IF(AND(E9>0,AB9>0),MIN(E9,AB9),"-") -> 3 | AZ9: =IF(AND(F9>0,AC9>0),MIN(F9,AC9),"-") -> 5 | BA9: =IF(AND(G9>0,AD9>0),MIN(G9,AD9),"-") -> 5 | BB9: =IF(AND(H9>0,AE9>0),MIN(H9,AE9),"-") -> 5 | BC9: =IF(AND(I9>0,AF9>0),MIN(I9,AF9),"-") -> 3 | BD9: =IF(AND(J9>0,AG9>0),MIN(J9,AG9),"-") -> 5 | BE9: =IF(AND(K9>0,AH9>0),MIN(K9,AH9),"-") -> 5 | BF9: =IF(AND(L9>0,AI9>0),MIN(L9,AI9),"-") -> 4 | BG9: =IF(COUNTIF(AX9:BF9,"<>-")=9,SUM(AX9:BF9),"-") -> 40 | BH9: =IF(AND(N9>0,AK9>0),MIN(N9,AK9),"-") -> 7 | BI9: =IF(AND(O9>0,AL9>0),MIN(O9,AL9),"-") -> 4 | BJ9: =IF(AND(P9>0,AM9>0),MIN(P9,AM9),"-") -> 3 | BK9: =IF(AND(Q9>0,AN9>0),MIN(Q9,AN9),"-") -> 6 | BL9: =IF(AND(R9>0,AO9>0),MIN(R9,AO9),"-") -> 3 | BM9: =IF(AND(S9>0,AP9>0),MIN(S9,AP9),"-") -> 6 | BN9: =IF(AND(T9>0,AQ9>0),MIN(T9,AQ9),"-") -> 3 | BO9: =IF(AND(U9>0,AR9>0),MIN(U9,AR9),"-") -> 6 | BP9: =IF(AND(V9>0,AS9>0),MIN(V9,AS9),"-") -> 5 | BQ9: =IF(COUNTIF(BH9:BP9,"<>-")=9,SUM(BH9:BP9),"-") -> 43 | BR9: =BG9 -> 40 | BS9: =IF(COUNTIF(BQ9:BR9,"<>-")=2,SUM(BQ9:BR9),"-") -> 83 | BT9: =IF(ISNUMBER(BS9),BS9-(C9*Rules!$P$9/100),"-") -> 79 | BU9: =RANK($BT9,$BT$5:$BT$106,1)+COUNTIF(BT$5:BT9,BT9)-1 -> 3 | BV9: =RANK(BT9,$BT$5:$BT$215,1) -> 3 | BW9: =B9 -> ANITA VAN DER LINDE | BX9: =C9 -> 16 | BY9: =BT9 -> 79 | CC9: 5 | CD9: =VLOOKUP(CC9,$BU$5:BY$215,2,FALSE) -> 4 | CE9: =VLOOKUP(CC9,$BU$5:BY$215,3,FALSE) -> GAIL SPEIRS | CF9: =VLOOKUP(CC9,$BU$5:BY$215,5,FALSE) -> 80 | CL9: 1
A10: 6 | B10: ='A Div'!A10 & " " & 'A Div'!B10 -> SHAY BROEDELET | C10: ='A Div'!E10 -> 28 | D10: 6 | E10: 3 | F10: 7 | G10: 6 | H10: 6 | I10: 4 | J10: 7 | K10: 7 | L10: 4 | M10: =IF(COUNTIF(D10:L10,"<>"&"")=9,SUM(D10:L10),"-") -> 50 | N10: 7 | O10: 4 | P10: 6 | Q10: 6 | R10: 3 | S10: 7 | T10: 5 | U10: 9 | V10: 10 | W10: =IF(COUNTIF(N10:V10,"<>"&"")=9,SUM(N10:V10),"-") -> 57 | X10: =IF(AND(ISNUMBER(M10),ISNUMBER(W10)),M10+W10,"-") -> 107 | Y10: =IF(ISNUMBER(X10),X10-C10,"-") -> 79 | AA10: 6 | AB10: 4 | AC10: 5 | AD10: 7 | AE10: 6 | AF10: 4 | AG10: 7 | AH10: 5 | AI10: 6 | AJ10: =IF(COUNTIF(AA10:AI10,"<>"&"")=9,SUM(AA10:AI10),"-") -> 50 | AK10: 8 | AL10: 5 | AM10: 3 | AN10: 7 | AO10: 4 | AP10: 6 | AQ10: 5 | AR10: 7 | AS10: 8 | AT10: =IF(COUNTIF(AK10:AS10,"<>"&"")=9,SUM(AK10:AS10),"-") -> 53 | AU10: =IF(AND(ISNUMBER(AJ10),ISNUMBER(AT10)),AJ10+AT10,"-") -> 103 | AV10: =IF(ISNUMBER(AU10),AU10-C10,"-") -> 75 | AX10: =IF(AND(D10>0,AA10>0),MIN(D10,AA10),"-") -> 6 | AY10: =IF(AND(E10>0,AB10>0),MIN(E10,AB10),"-") -> 3 | AZ10: =IF(AND(F10>0,AC10>0),MIN(F10,AC10),"-") -> 5 | BA10: =IF(AND(G10>0,AD10>0),MIN(G10,AD10),"-") -> 6 | BB10: =IF(AND(H10>0,AE10>0),MIN(H10,AE10),"-") -> 6 | BC10: =IF(AND(I10>0,AF10>0),MIN(I10,AF10),"-") -> 4 | BD10: =IF(AND(J10>0,AG10>0),MIN(J10,AG10),"-") -> 7 | BE10: =IF(AND(K10>0,AH10>0),MIN(K10,AH10),"-") -> 5 | BF10: =IF(AND(L10>0,AI10>0),MIN(L10,AI10),"-") -> 4 | BG10: =IF(COUNTIF(AX10:BF10,"<>-")=9,SUM(AX10:BF10),"-") -> 46 | BH10: =IF(AND(N10>0,AK10>0),MIN(N10,AK10),"-") -> 7 | BI10: =IF(AND(O10>0,AL10>0),MIN(O10,AL10),"-") -> 4 | BJ10: =IF(AND(P10>0,AM10>0),MIN(P10,AM10),"-") -> 3 | BK10: =IF(AND(Q10>0,AN10>0),MIN(Q10,AN10),"-") -> 6 | BL10: =IF(AND(R10>0,AO10>0),MIN(R10,AO10),"-") -> 3 | BM10: =IF(AND(S10>0,AP10>0),MIN(S10,AP10),"-") -> 6 | BN10: =IF(AND(T10>0,AQ10>0),MIN(T10,AQ10),"-") -> 5 | BO10: =IF(AND(U10>0,AR10>0),MIN(U10,AR10),"-") -> 7 | BP10: =IF(AND(V10>0,AS10>0),MIN(V10,AS10),"-") -> 8 | BQ10: =IF(COUNTIF(BH10:BP10,"<>-")=9,SUM(BH10:BP10),"-") -> 49 | BR10: =BG10 -> 46 | BS10: =IF(COUNTIF(BQ10:BR10,"<>-")=2,SUM(BQ10:BR10),"-") -> 95 | BT10: =IF(ISNUMBER(BS10),BS10-(C10*Rules!$P$9/100),"-") -> 88 | BU10: =RANK($BT10,$BT$5:$BT$106,1)+COUNTIF(BT$5:BT10,BT10)-1 -> 15 | BV10: =RANK(BT10,$BT$5:$BT$215,1) -> 15 | BW10: =B10 -> SHAY BROEDELET | BX10: =C10 -> 28 | BY10: =BT10 -> 88 | CC10: 6 | CD10: =VLOOKUP(CC10,$BU$5:BY$215,2,FALSE) -> 6 | CE10: =VLOOKUP(CC10,$BU$5:BY$215,3,FALSE) -> JUDY VAN DER VEEN | CF10: =VLOOKUP(CC10,$BU$5:BY$215,5,FALSE) -> 80.5 | CL10: 1
A11: 7 | B11: ='A Div'!A11 & " " & 'A Div'!B11 -> PREM GOVENDER | C11: ='A Div'!E11 -> 26 | D11: 6 | E11: 3 | F11: 6 | G11: 4 | H11: 7 | I11: 4 | J11: 5 | K11: 6 | L11: 5 | M11: =IF(COUNTIF(D11:L11,"<>"&"")=9,SUM(D11:L11),"-") -> 46 | N11: 8 | O11: 5 | P11: 4 | Q11: 7 | R11: 3 | S11: 6 | T11: 6 | U11: 6 | V11: 8 | W11: =IF(COUNTIF(N11:V11,"<>"&"")=9,SUM(N11:V11),"-") -> 53 | X11: =IF(AND(ISNUMBER(M11),ISNUMBER(W11)),M11+W11,"-") -> 99 | Y11: =IF(ISNUMBER(X11),X11-C11,"-") -> 73 | AA11: 6 | AB11: 4 | AC11: 5 | AD11: 6 | AE11: 11 | AF11: 5 | AG11: 6 | AH11: 5 | AI11: 6 | AJ11: =IF(COUNTIF(AA11:AI11,"<>"&"")=9,SUM(AA11:AI11),"-") -> 54 | AK11: 9 | AL11: 7 | AM11: 3 | AN11: 6 | AO11: 4 | AP11: 7 | AQ11: 5 | AR11: 7 | AS11: 7 | AT11: =IF(COUNTIF(AK11:AS11,"<>"&"")=9,SUM(AK11:AS11),"-") -> 55 | AU11: =IF(AND(ISNUMBER(AJ11),ISNUMBER(AT11)),AJ11+AT11,"-") -> 109 | AV11: =IF(ISNUMBER(AU11),AU11-C11,"-") -> 83 | AX11: =IF(AND(D11>0,AA11>0),MIN(D11,AA11),"-") -> 6 | AY11: =IF(AND(E11>0,AB11>0),MIN(E11,AB11),"-") -> 3 | AZ11: =IF(AND(F11>0,AC11>0),MIN(F11,AC11),"-") -> 5 | BA11: =IF(AND(G11>0,AD11>0),MIN(G11,AD11),"-") -> 4 | BB11: =IF(AND(H11>0,AE11>0),MIN(H11,AE11),"-") -> 7 | BC11: =IF(AND(I11>0,AF11>0),MIN(I11,AF11),"-") -> 4 | BD11: =IF(AND(J11>0,AG11>0),MIN(J11,AG11),"-") -> 5 | BE11: =IF(AND(K11>0,AH11>0),MIN(K11,AH11),"-") -> 5 | BF11: =IF(AND(L11>0,AI11>0),MIN(L11,AI11),"-") -> 5 | BG11: =IF(COUNTIF(AX11:BF11,"<>-")=9,SUM(AX11:BF11),"-") -> 44 | BH11: =IF(AND(N11>0,AK11>0),MIN(N11,AK11),"-") -> 8 | BI11: =IF(AND(O11>0,AL11>0),MIN(O11,AL11),"-") -> 5 | BJ11: =IF(AND(P11>0,AM11>0),MIN(P11,AM11),"-") -> 3 | BK11: =IF(AND(Q11>0,AN11>0),MIN(Q11,AN11),"-") -> 6 | BL11: =IF(AND(R11>0,AO11>0),MIN(R11,AO11),"-") -> 3 | BM11: =IF(AND(S11>0,AP11>0),MIN(S11,AP11),"-") -> 6 | BN11: =IF(AND(T11>0,AQ11>0),MIN(T11,AQ11),"-") -> 5 | BO11: =IF(AND(U11>0,AR11>0),MIN(U11,AR11),"-") -> 6 | BP11: =IF(AND(V11>0,AS11>0),MIN(V11,AS11),"-") -> 7 | BQ11: =IF(COUNTIF(BH11:BP11,"<>-")=9,SUM(BH11:BP11),"-") -> 49 | BR11: =BG11 -> 44 | BS11: =IF(COUNTIF(BQ11:BR11,"<>-")=2,SUM(BQ11:BR11),"-") -> 93 | BT11: =IF(ISNUMBER(BS11),BS11-(C11*Rules!$P$9/100),"-") -> 86.5 | BU11: =RANK($BT11,$BT$5:$BT$106,1)+COUNTIF(BT$5:BT11,BT11)-1 -> 13 | BV11: =RANK(BT11,$BT$5:$BT$215,1) -> 13 | BW11: =B11 -> PREM GOVENDER | BX11: =C11 -> 26 | BY11: =BT11 -> 86.5 | CC11: 7 | CD11: =VLOOKUP(CC11,$BU$5:BY$215,2,FALSE) -> 7 | CE11: =VLOOKUP(CC11,$BU$5:BY$215,3,FALSE) -> SONJA HOPCROFT | CF11: =VLOOKUP(CC11,$BU$5:BY$215,5,FALSE) -> 80.75 | CL11: 1
A12: 8 | B12: ='A Div'!A12 & " " & 'A Div'!B12 -> RENE LADELL | C12: ='A Div'!E12 -> 36 | D12: 7 | E12: 3 | F12: 7 | G12: 7 | H12: 9 | I12: 5 | J12: 7 | K12: 6 | L12: 5 | M12: =IF(COUNTIF(D12:L12,"<>"&"")=9,SUM(D12:L12),"-") -> 56 | N12: 9 | O12: 7 | P12: 3 | Q12: 8 | R12: 4 | S12: 7 | T12: 6 | U12: 8 | V12: 7 | W12: =IF(COUNTIF(N12:V12,"<>"&"")=9,SUM(N12:V12),"-") -> 59 | X12: =IF(AND(ISNUMBER(M12),ISNUMBER(W12)),M12+W12,"-") -> 115 | Y12: =IF(ISNUMBER(X12),X12-C12,"-") -> 79 | AA12: 6 | AB12: 4 | AC12: 7 | AD12: 6 | AE12: 7 | AF12: 3 | AG12: 6 | AH12: 7 | AI12: 7 | AJ12: =IF(COUNTIF(AA12:AI12,"<>"&"")=9,SUM(AA12:AI12),"-") -> 53 | AK12: 10 | AL12: 6 | AM12: 4 | AN12: 8 | AO12: 5 | AP12: 8 | AQ12: 6 | AR12: 7 | AS12: 8 | AT12: =IF(COUNTIF(AK12:AS12,"<>"&"")=9,SUM(AK12:AS12),"-") -> 62 | AU12: =IF(AND(ISNUMBER(AJ12),ISNUMBER(AT12)),AJ12+AT12,"-") -> 115 | AV12: =IF(ISNUMBER(AU12),AU12-C12,"-") -> 79 | AX12: =IF(AND(D12>0,AA12>0),MIN(D12,AA12),"-") -> 6 | AY12: =IF(AND(E12>0,AB12>0),MIN(E12,AB12),"-") -> 3 | AZ12: =IF(AND(F12>0,AC12>0),MIN(F12,AC12),"-") -> 7 | BA12: =IF(AND(G12>0,AD12>0),MIN(G12,AD12),"-") -> 6 | BB12: =IF(AND(H12>0,AE12>0),MIN(H12,AE12),"-") -> 7 | BC12: =IF(AND(I12>0,AF12>0),MIN(I12,AF12),"-") -> 3 | BD12: =IF(AND(J12>0,AG12>0),MIN(J12,AG12),"-") -> 6 | BE12: =IF(AND(K12>0,AH12>0),MIN(K12,AH12),"-") -> 6 | BF12: =IF(AND(L12>0,AI12>0),MIN(L12,AI12),"-") -> 5 | BG12: =IF(COUNTIF(AX12:BF12,"<>-")=9,SUM(AX12:BF12),"-") -> 49 | BH12: =IF(AND(N12>0,AK12>0),MIN(N12,AK12),"-") -> 9 | BI12: =IF(AND(O12>0,AL12>0),MIN(O12,AL12),"-") -> 6 | BJ12: =IF(AND(P12>0,AM12>0),MIN(P12,AM12),"-") -> 3 | BK12: =IF(AND(Q12>0,AN12>0),MIN(Q12,AN12),"-") -> 8 | BL12: =IF(AND(R12>0,AO12>0),MIN(R12,AO12),"-") -> 4 | BM12: =IF(AND(S12>0,AP12>0),MIN(S12,AP12),"-") -> 7 | BN12: =IF(AND(T12>0,AQ12>0),MIN(T12,AQ12),"-") -> 6 | BO12: =IF(AND(U12>0,AR12>0),MIN(U12,AR12),"-") -> 7 | BP12: =IF(AND(V12>0,AS12>0),MIN(V12,AS12),"-") -> 7 | BQ12: =IF(COUNTIF(BH12:BP12,"<>-")=9,SUM(BH12:BP12),"-") -> 57 | BR12: =BG12 -> 49 | BS12: =IF(COUNTIF(BQ12:BR12,"<>-")=2,SUM(BQ12:BR12),"-") -> 106 | BT12: =IF(ISNUMBER(BS12),BS12-(C12*Rules!$P$9/100),"-") -> 97 | BU12: =RANK($BT12,$BT$5:$BT$106,1)+COUNTIF(BT$5:BT12,BT12)-1 -> 16 | BV12: =RANK(BT12,$BT$5:$BT$215,1) -> 16 | BW12: =B12 -> RENE LADELL | BX12: =C12 -> 36 | BY12: =BT12 -> 97 | CC12: 8 | CD12: =VLOOKUP(CC12,$BU$5:BY$215,2,FALSE) -> 8 | CE12: =VLOOKUP(CC12,$BU$5:BY$215,3,FALSE) -> JANIS NEL | CF12: =VLOOKUP(CC12,$BU$5:BY$215,5,FALSE) -> 81 | CL12: 1
A13: 9 | B13: ='A Div'!A13 & " " & 'A Div'!B13 -> ANGELA MASEFIELD | C13: ='A Div'!E13 -> 22 | D13: 5 | E13: 5 | F13: 8 | G13: 5 | H13: 7 | I13: 3 | J13: 5 | K13: 5 | L13: 4 | M13: =IF(COUNTIF(D13:L13,"<>"&"")=9,SUM(D13:L13),"-") -> 47 | N13: 8 | O13: 6 | P13: 4 | Q13: 6 | R13: 5 | S13: 6 | T13: 5 | U13: 5 | V13: 9 | W13: =IF(COUNTIF(N13:V13,"<>"&"")=9,SUM(N13:V13),"-") -> 54 | X13: =IF(AND(ISNUMBER(M13),ISNUMBER(W13)),M13+W13,"-") -> 101 | Y13: =IF(ISNUMBER(X13),X13-C13,"-") -> 79 | AA13: 5 | AB13: 4 | AC13: 8 | AD13: 6 | AE13: 6 | AF13: 5 | AG13: 8 | AH13: 7 | AI13: 6 | AJ13: =IF(COUNTIF(AA13:AI13,"<>"&"")=9,SUM(AA13:AI13),"-") -> 55 | AK13: 6 | AL13: 6 | AM13: 3 | AN13: 7 | AO13: 4 | AP13: 7 | AQ13: 5 | AR13: 5 | AS13: 7 | AT13: =IF(COUNTIF(AK13:AS13,"<>"&"")=9,SUM(AK13:AS13),"-") -> 50 | AU13: =IF(AND(ISNUMBER(AJ13),ISNUMBER(AT13)),AJ13+AT13,"-") -> 105 | AV13: =IF(ISNUMBER(AU13),AU13-C13,"-") -> 83 | AX13: =IF(AND(D13>0,AA13>0),MIN(D13,AA13),"-") -> 5 | AY13: =IF(AND(E13>0,AB13>0),MIN(E13,AB13),"-") -> 4 | AZ13: =IF(AND(F13>0,AC13>0),MIN(F13,AC13),"-") -> 8 | BA13: =IF(AND(G13>0,AD13>0),MIN(G13,AD13),"-") -> 5 | BB13: =IF(AND(H13>0,AE13>0),MIN(H13,AE13),"-") -> 6 | BC13: =IF(AND(I13>0,AF13>0),MIN(I13,AF13),"-") -> 3 | BD13: =IF(AND(J13>0,AG13>0),MIN(J13,AG13),"-") -> 5 | BE13: =IF(AND(K13>0,AH13>0),MIN(K13,AH13),"-") -> 5 | BF13: =IF(AND(L13>0,AI13>0),MIN(L13,AI13),"-") -> 4 | BG13: =IF(COUNTIF(AX13:BF13,"<>-")=9,SUM(AX13:BF13),"-") -> 45 | BH13: =IF(AND(N13>0,AK13>0),MIN(N13,AK13),"-") -> 6 | BI13: =IF(AND(O13>0,AL13>0),MIN(O13,AL13),"-") -> 6 | BJ13: =IF(AND(P13>0,AM13>0),MIN(P13,AM13),"-") -> 3 | BK13: =IF(AND(Q13>0,AN13>0),MIN(Q13,AN13),"-") -> 6 | BL13: =IF(AND(R13>0,AO13>0),MIN(R13,AO13),"-") -> 4 | BM13: =IF(AND(S13>0,AP13>0),MIN(S13,AP13),"-") -> 6 | BN13: =IF(AND(T13>0,AQ13>0),MIN(T13,AQ13),"-") -> 5 | BO13: =IF(AND(U13>0,AR13>0),MIN(U13,AR13),"-") -> 5 | BP13: =IF(AND(V13>0,AS13>0),MIN(V13,AS13),"-") -> 7 | BQ13: =IF(COUNTIF(BH13:BP13,"<>-")=9,SUM(BH13:BP13),"-") -> 48 | BR13: =BG13 -> 45 | BS13: =IF(COUNTIF(BQ13:BR13,"<>-")=2,SUM(BQ13:BR13),"-") -> 93 | BT13: =IF(ISNUMBER(BS13),BS13-(C13*Rules!$P$9/100),"-") -> 87.5 | BU13: =RANK($BT13,$BT$5:$BT$106,1)+COUNTIF(BT$5:BT13,BT13)-1 -> 14 | BV13: =RANK(BT13,$BT$5:$BT$215,1) -> 14 | BW13: =B13 -> ANGELA MASEFIELD | BX13: =C13 -> 22 | BY13: =BT13 -> 87.5 | CC13: 9 | CD13: =VLOOKUP(CC13,$BU$5:BY$215,2,FALSE) -> 9 | CE13: =VLOOKUP(CC13,$BU$5:BY$215,3,FALSE) -> ALIDA HOOPER | CF13: =VLOOKUP(CC13,$BU$5:BY$215,5,FALSE) -> 81.25 | CL13: 1
A14: 10 | B14: ='A Div'!A14 & " " & 'A Div'!B14 -> FIFI NARAN | C14: ='A Div'!E14 -> 25 | D14: 5 | E14: 3 | F14: 5 | G14: 6 | H14: 8 | I14: 5 | J14: 7 | K14: 6 | L14: 3 | M14: =IF(COUNTIF(D14:L14,"<>"&"")=9,SUM(D14:L14),"-") -> 48 | N14: 6 | O14: 7 | P14: 6 | Q14: 7 | R14: 4 | S14: 6 | T14: 5 | U14: 6 | V14: 7 | W14: =IF(COUNTIF(N14:V14,"<>"&"")=9,SUM(N14:V14),"-") -> 54 | X14: =IF(AND(ISNUMBER(M14),ISNUMBER(W14)),M14+W14,"-") -> 102 | Y14: =IF(ISNUMBER(X14),X14-C14,"-") -> 77 | AA14: 6 | AB14: 3 | AC14: 7 | AD14: 5 | AE14: 8 | AF14: 4 | AG14: 4 | AH14: 5 | AI14: 4 | AJ14: =IF(COUNTIF(AA14:AI14,"<>"&"")=9,SUM(AA14:AI14),"-") -> 46 | AK14: 6 | AL14: 5 | AM14: 5 | AN14: 6 | AO14: 7 | AP14: 7 | AQ14: 4 | AR14: 9 | AS14: 8 | AT14: =IF(COUNTIF(AK14:AS14,"<>"&"")=9,SUM(AK14:AS14),"-") -> 57 | AU14: =IF(AND(ISNUMBER(AJ14),ISNUMBER(AT14)),AJ14+AT14,"-") -> 103 | AV14: =IF(ISNUMBER(AU14),AU14-C14,"-") -> 78 | AX14: =IF(AND(D14>0,AA14>0),MIN(D14,AA14),"-") -> 5 | AY14: =IF(AND(E14>0,AB14>0),MIN(E14,AB14),"-") -> 3 | AZ14: =IF(AND(F14>0,AC14>0),MIN(F14,AC14),"-") -> 5 | BA14: =IF(AND(G14>0,AD14>0),MIN(G14,AD14),"-") -> 5 | BB14: =IF(AND(H14>0,AE14>0),MIN(H14,AE14),"-") -> 8 | BC14: =IF(AND(I14>0,AF14>0),MIN(I14,AF14),"-") -> 4 | BD14: =IF(AND(J14>0,AG14>0),MIN(J14,AG14),"-") -> 4 | BE14: =IF(AND(K14>0,AH14>0),MIN(K14,AH14),"-") -> 5 | BF14: =IF(AND(L14>0,AI14>0),MIN(L14,AI14),"-") -> 3 | BG14: =IF(COUNTIF(AX14:BF14,"<>-")=9,SUM(AX14:BF14),"-") -> 42 | BH14: =IF(AND(N14>0,AK14>0),MIN(N14,AK14),"-") -> 6 | BI14: =IF(AND(O14>0,AL14>0),MIN(O14,AL14),"-") -> 5 | BJ14: =IF(AND(P14>0,AM14>0),MIN(P14,AM14),"-") -> 5 | BK14: =IF(AND(Q14>0,AN14>0),MIN(Q14,AN14),"-") -> 6 | BL14: =IF(AND(R14>0,AO14>0),MIN(R14,AO14),"-") -> 4 | BM14: =IF(AND(S14>0,AP14>0),MIN(S14,AP14),"-") -> 6 | BN14: =IF(AND(T14>0,AQ14>0),MIN(T14,AQ14),"-") -> 4 | BO14: =IF(AND(U14>0,AR14>0),MIN(U14,AR14),"-") -> 6 | BP14: =IF(AND(V14>0,AS14>0),MIN(V14,AS14),"-") -> 7 | BQ14: =IF(COUNTIF(BH14:BP14,"<>-")=9,SUM(BH14:BP14),"-") -> 49 | BR14: =BG14 -> 42 | BS14: =IF(COUNTIF(BQ14:BR14,"<>-")=2,SUM(BQ14:BR14),"-") -> 91 | BT14: =IF(ISNUMBER(BS14),BS14-(C14*Rules!$P$9/100),"-") -> 84.75 | BU14: =RANK($BT14,$BT$5:$BT$106,1)+COUNTIF(BT$5:BT14,BT14)-1 -> 11 | BV14: =RANK(BT14,$BT$5:$BT$215,1) -> 11 | BW14: =B14 -> FIFI NARAN | BX14: =C14 -> 25 | BY14: =BT14 -> 84.75 | CC14: 10 | CD14: =VLOOKUP(CC14,$BU$5:BY$215,2,FALSE) -> 10 | CE14: =VLOOKUP(CC14,$BU$5:BY$215,3,FALSE) -> KAREN STOTT | CF14: =VLOOKUP(CC14,$BU$5:BY$215,5,FALSE) -> 82 | CL14: 1
A15: 11 | B15: ='A Div'!A15 & " " & 'A Div'!B15 -> JANIS NEL | C15: ='A Div'!E15 -> 20 | D15: 5 | E15: 2 | F15: 6 | G15: 5 | H15: 7 | I15: 3 | J15: 6 | K15: 5 | L15: 5 | M15: =IF(COUNTIF(D15:L15,"<>"&"")=9,SUM(D15:L15),"-") -> 44 | N15: 5 | O15: 4 | P15: 3 | Q15: 6 | R15: 4 | S15: 6 | T15: 4 | U15: 5 | V15: 6 | W15: =IF(COUNTIF(N15:V15,"<>"&"")=9,SUM(N15:V15),"-") -> 43 | X15: =IF(AND(ISNUMBER(M15),ISNUMBER(W15)),M15+W15,"-") -> 87 | Y15: =IF(ISNUMBER(X15),X15-C15,"-") -> 67 | AA15: 5 | AB15: 3 | AC15: 5 | AD15: 6 | AE15: 8 | AF15: 3 | AG15: 6 | AH15: 6 | AI15: 5 | AJ15: =IF(COUNTIF(AA15:AI15,"<>"&"")=9,SUM(AA15:AI15),"-") -> 47 | AK15: 6 | AL15: 4 | AM15: 3 | AN15: 7 | AO15: 4 | AP15: 8 | AQ15: 4 | AR15: 6 | AS15: 6 | AT15: =IF(COUNTIF(AK15:AS15,"<>"&"")=9,SUM(AK15:AS15),"-") -> 48 | AU15: =IF(AND(ISNUMBER(AJ15),ISNUMBER(AT15)),AJ15+AT15,"-") -> 95 | AV15: =IF(ISNUMBER(AU15),AU15-C15,"-") -> 75 | AX15: =IF(AND(D15>0,AA15>0),MIN(D15,AA15),"-") -> 5 | AY15: =IF(AND(E15>0,AB15>0),MIN(E15,AB15),"-") -> 2 | AZ15: =IF(AND(F15>0,AC15>0),MIN(F15,AC15),"-") -> 5 | BA15: =IF(AND(G15>0,AD15>0),MIN(G15,AD15),"-") -> 5 | BB15: =IF(AND(H15>0,AE15>0),MIN(H15,AE15),"-") -> 7 | BC15: =IF(AND(I15>0,AF15>0),MIN(I15,AF15),"-") -> 3 | BD15: =IF(AND(J15>0,AG15>0),MIN(J15,AG15),"-") -> 6 | BE15: =IF(AND(K15>0,AH15>0),MIN(K15,AH15),"-") -> 5 | BF15: =IF(AND(L15>0,AI15>0),MIN(L15,AI15),"-") -> 5 | BG15: =IF(COUNTIF(AX15:BF15,"<>-")=9,SUM(AX15:BF15),"-") -> 43 | BH15: =IF(AND(N15>0,AK15>0),MIN(N15,AK15),"-") -> 5 | BI15: =IF(AND(O15>0,AL15>0),MIN(O15,AL15),"-") -> 4 | BJ15: =IF(AND(P15>0,AM15>0),MIN(P15,AM15),"-") -> 3 | BK15: =IF(AND(Q15>0,AN15>0),MIN(Q15,AN15),"-") -> 6 | BL15: =IF(AND(R15>0,AO15>0),MIN(R15,AO15),"-") -> 4 | BM15: =IF(AND(S15>0,AP15>0),MIN(S15,AP15),"-") -> 6 | BN15: =IF(AND(T15>0,AQ15>0),MIN(T15,AQ15),"-") -> 4 | BO15: =IF(AND(U15>0,AR15>0),MIN(U15,AR15),"-") -> 5 | BP15: =IF(AND(V15>0,AS15>0),MIN(V15,AS15),"-") -> 6 | BQ15: =IF(COUNTIF(BH15:BP15,"<>-")=9,SUM(BH15:BP15),"-") -> 43 | BR15: =BG15 -> 43 | BS15: =IF(COUNTIF(BQ15:BR15,"<>-")=2,SUM(BQ15:BR15),"-") -> 86 | BT15: =IF(ISNUMBER(BS15),BS15-(C15*Rules!$P$9/100),"-") -> 81 | BU15: =RANK($BT15,$BT$5:$BT$106,1)+COUNTIF(BT$5:BT15,BT15)-1 -> 8 | BV15: =RANK(BT15,$BT$5:$BT$215,1) -> 8 | BW15: =B15 -> JANIS NEL | BX15: =C15 -> 20 | BY15: =BT15 -> 81 | CC15: 11 | CD15: =VLOOKUP(CC15,$BU$5:BY$215,2,FALSE) -> 11 | CE15: =VLOOKUP(CC15,$BU$5:BY$215,3,FALSE) -> FIFI NARAN | CF15: =VLOOKUP(CC15,$BU$5:BY$215,5,FALSE) -> 84.75 | CL15: 1
A16: 12 | B16: ='A Div'!A16 & " " & 'A Div'!B16 -> MELISSA PALMER | C16: ='A Div'!E16 -> 20 | D16: 6 | E16: 3 | F16: 6 | G16: 4 | H16: 7 | I16: 3 | J16: 5 | K16: 5 | L16: 5 | M16: =IF(COUNTIF(D16:L16,"<>"&"")=9,SUM(D16:L16),"-") -> 44 | N16: 7 | O16: 4 | P16: 4 | Q16: 7 | R16: 6 | S16: 6 | T16: 3 | U16: 5 | V16: 4 | W16: =IF(COUNTIF(N16:V16,"<>"&"")=9,SUM(N16:V16),"-") -> 46 | X16: =IF(AND(ISNUMBER(M16),ISNUMBER(W16)),M16+W16,"-") -> 90 | Y16: =IF(ISNUMBER(X16),X16-C16,"-") -> 70 | AA16: 5 | AB16: 5 | AC16: 4 | AD16: 6 | AE16: 10 | AF16: 5 | AG16: 6 | AH16: 5 | AI16: 5 | AJ16: =IF(COUNTIF(AA16:AI16,"<>"&"")=9,SUM(AA16:AI16),"-") -> 51 | AK16: 10 | AL16: 5 | AM16: 4 | AN16: 6 | AO16: 4 | AP16: 5 | AQ16: 4 | AR16: 6 | AS16: 5.1 | AT16: =IF(COUNTIF(AK16:AS16,"<>"&"")=9,SUM(AK16:AS16),"-") -> 49.1 | AU16: =IF(AND(ISNUMBER(AJ16),ISNUMBER(AT16)),AJ16+AT16,"-") -> 100.1 | AV16: =IF(ISNUMBER(AU16),AU16-C16,"-") -> 80.1 | AX16: =IF(AND(D16>0,AA16>0),MIN(D16,AA16),"-") -> 5 | AY16: =IF(AND(E16>0,AB16>0),MIN(E16,AB16),"-") -> 3 | AZ16: =IF(AND(F16>0,AC16>0),MIN(F16,AC16),"-") -> 4 | BA16: =IF(AND(G16>0,AD16>0),MIN(G16,AD16),"-") -> 4 | BB16: =IF(AND(H16>0,AE16>0),MIN(H16,AE16),"-") -> 7 | BC16: =IF(AND(I16>0,AF16>0),MIN(I16,AF16),"-") -> 3 | BD16: =IF(AND(J16>0,AG16>0),MIN(J16,AG16),"-") -> 5 | BE16: =IF(AND(K16>0,AH16>0),MIN(K16,AH16),"-") -> 5 | BF16: =IF(AND(L16>0,AI16>0),MIN(L16,AI16),"-") -> 5 | BG16: =IF(COUNTIF(AX16:BF16,"<>-")=9,SUM(AX16:BF16),"-") -> 41 | BH16: =IF(AND(N16>0,AK16>0),MIN(N16,AK16),"-") -> 7 | BI16: =IF(AND(O16>0,AL16>0),MIN(O16,AL16),"-") -> 4 | BJ16: =IF(AND(P16>0,AM16>0),MIN(P16,AM16),"-") -> 4 | BK16: =IF(AND(Q16>0,AN16>0),MIN(Q16,AN16),"-") -> 6 | BL16: =IF(AND(R16>0,AO16>0),MIN(R16,AO16),"-") -> 4 | BM16: =IF(AND(S16>0,AP16>0),MIN(S16,AP16),"-") -> 5 | BN16: =IF(AND(T16>0,AQ16>0),MIN(T16,AQ16),"-") -> 3 | BO16: =IF(AND(U16>0,AR16>0),MIN(U16,AR16),"-") -> 5 | BP16: =IF(AND(V16>0,AS16>0),MIN(V16,AS16),"-") -> 4 | BQ16: =IF(COUNTIF(BH16:BP16,"<>-")=9,SUM(BH16:BP16),"-") -> 42 | BR16: =BG16 -> 41 | BS16: =IF(COUNTIF(BQ16:BR16,"<>-")=2,SUM(BQ16:BR16),"-") -> 83 | BT16: =IF(ISNUMBER(BS16),BS16-(C16*Rules!$P$9/100),"-") -> 78 | BU16: =RANK($BT16,$BT$5:$BT$106,1)+COUNTIF(BT$5:BT16,BT16)-1 -> 2 | BV16: =RANK(BT16,$BT$5:$BT$215,1) -> 2 | BW16: =B16 -> MELISSA PALMER | BX16: =C16 -> 20 | BY16: =BT16 -> 78 | CC16: 12 | CD16: =VLOOKUP(CC16,$BU$5:BY$215,2,FALSE) -> 12 | CE16: =VLOOKUP(CC16,$BU$5:BY$215,3,FALSE) -> MELISSA SAVIO | CF16: =VLOOKUP(CC16,$BU$5:BY$215,5,FALSE) -> 85.25 | CL16: 1
... A20: 16 | B20: ='A Div'!A20 & " " & 'A Div'!B20 -> JUDY VAN DER VEEN | C20: ='A Div'!E20 -> 22 | D20: 5 | E20: 4 | F20: 5 | G20: 7 | H20: 5 | I20: 4 | J20: 6 | K20: 5 | L20: 4 | M20: =IF(COUNTIF(D20:L20,"<>"&"")=9,SUM(D20:L20),"-") -> 45 | N20: 7 | O20: 5 | P20: 4 | Q20: 6 | R20: 5 | S20: 6 | T20: 6 | U20: 6 | V20: 5 | W20: =IF(COUNTIF(N20:V20,"<>"&"")=9,SUM(N20:V20),"-") -> 50 | X20: =IF(AND(ISNUMBER(M20),ISNUMBER(W20)),M20+W20,"-") -> 95 | Y20: =IF(ISNUMBER(X20),X20-C20,"-") -> 73 | AA20: 5 | AB20: 3 | AC20: 7 | AD20: 5 | AE20: 6 | AF20: 3 | AG20: 7 | AH20: 6 | AI20: 5 | AJ20: =IF(COUNTIF(AA20:AI20,"<>"&"")=9,SUM(AA20:AI20),"-") -> 47 | AK20: 7 | AL20: 5 | AM20: 5 | AN20: 5 | AO20: 3 | AP20: 5 | AQ20: 5 | AR20: 7 | AS20: 6 | AT20: =IF(COUNTIF(AK20:AS20,"<>"&"")=9,SUM(AK20:AS20),"-") -> 48 | AU20: =IF(AND(ISNUMBER(AJ20),ISNUMBER(AT20)),AJ20+AT20,"-") -> 95 | AV20: =IF(ISNUMBER(AU20),AU20-C20,"-") -> 73 | AX20: =IF(AND(D20>0,AA20>0),MIN(D20,AA20),"-") -> 5 | AY20: =IF(AND(E20>0,AB20>0),MIN(E20,AB20),"-") -> 3 | AZ20: =IF(AND(F20>0,AC20>0),MIN(F20,AC20),"-") -> 5 | BA20: =IF(AND(G20>0,AD20>0),MIN(G20,AD20),"-") -> 5 | BB20: =IF(AND(H20>0,AE20>0),MIN(H20,AE20),"-") -> 5 | BC20: =IF(AND(I20>0,AF20>0),MIN(I20,AF20),"-") -> 3 | BD20: =IF(AND(J20>0,AG20>0),MIN(J20,AG20),"-") -> 6 | BE20: =IF(AND(K20>0,AH20>0),MIN(K20,AH20),"-") -> 5 | BF20: =IF(AND(L20>0,AI20>0),MIN(L20,AI20),"-") -> 4 | BG20: =IF(COUNTIF(AX20:BF20,"<>-")=9,SUM(AX20:BF20),"-") -> 41 | BH20: =IF(AND(N20>0,AK20>0),MIN(N20,AK20),"-") -> 7 | BI20: =IF(AND(O20>0,AL20>0),MIN(O20,AL20),"-") -> 5 | BJ20: =IF(AND(P20>0,AM20>0),MIN(P20,AM20),"-") -> 4 | BK20: =IF(AND(Q20>0,AN20>0),MIN(Q20,AN20),"-") -> 5 | BL20: =IF(AND(R20>0,AO20>0),MIN(R20,AO20),"-") -> 3 | BM20: =IF(AND(S20>0,AP20>0),MIN(S20,AP20),"-") -> 5 | BN20: =IF(AND(T20>0,AQ20>0),MIN(T20,AQ20),"-") -> 5 | BO20: =IF(AND(U20>0,AR20>0),MIN(U20,AR20),"-") -> 6 | BP20: =IF(AND(V20>0,AS20>0),MIN(V20,AS20),"-") -> 5 | BQ20: =IF(COUNTIF(BH20:BP20,"<>-")=9,SUM(BH20:BP20),"-") -> 45 | BR20: =BG20 -> 41 | BS20: =IF(COUNTIF(BQ20:BR20,"<>-")=2,SUM(BQ20:BR20),"-") -> 86 | BT20: =IF(ISNUMBER(BS20),BS20-(C20*Rules!$P$9/100),"-") -> 80.5 | BU20: =RANK($BT20,$BT$5:$BT$106,1)+COUNTIF(BT$5:BT20,BT20)-1 -> 6 | BV20: =RANK(BT20,$BT$5:$BT$215,1) -> 6 | BW20: =B20 -> JUDY VAN DER VEEN | BX20: =C20 -> 22 | BY20: =BT20 -> 80.5 | CC20: 16 | CD20: =VLOOKUP(CC20,$BU$5:BY$215,2,FALSE) -> 16 | CE20: =VLOOKUP(CC20,$BU$5:BY$215,3,FALSE) -> RENE LADELL | CF20: =VLOOKUP(CC20,$BU$5:BY$215,5,FALSE) -> 97 | CL20: 1
A21: 17 | B21: ='A Div'!A21 & " " & 'A Div'!B21 | C21: ='A Div'!E21 -> - | M21: =IF(COUNTIF(D21:L21,"<>"&"")=9,SUM(D21:L21),"-") -> - | W21: =IF(COUNTIF(N21:V21,"<>"&"")=9,SUM(N21:V21),"-") -> - | X21: =IF(AND(ISNUMBER(M21),ISNUMBER(W21)),M21+W21,"-") -> - | Y21: =IF(ISNUMBER(X21),X21-C21,"-") -> - | AJ21: =IF(COUNTIF(AA21:AI21,"<>"&"")=9,SUM(AA21:AI21),"-") -> - | AT21: =IF(COUNTIF(AK21:AS21,"<>"&"")=9,SUM(AK21:AS21),"-") -> - | AU21: =IF(AND(ISNUMBER(AJ21),ISNUMBER(AT21)),AJ21+AT21,"-") -> - | AV21: =IF(ISNUMBER(AU21),AU21-C21,"-") -> - | AX21: =IF(AND(D21>0,AA21>0),MIN(D21,AA21),"-") -> - | AY21: =IF(AND(E21>0,AB21>0),MIN(E21,AB21),"-") -> - | AZ21: =IF(AND(F21>0,AC21>0),MIN(F21,AC21),"-") -> - | BA21: =IF(AND(G21>0,AD21>0),MIN(G21,AD21),"-") -> - | BB21: =IF(AND(H21>0,AE21>0),MIN(H21,AE21),"-") -> - | BC21: =IF(AND(I21>0,AF21>0),MIN(I21,AF21),"-") -> - | BD21: =IF(AND(J21>0,AG21>0),MIN(J21,AG21),"-") -> - | BE21: =IF(AND(K21>0,AH21>0),MIN(K21,AH21),"-") -> - | BF21: =IF(AND(L21>0,AI21>0),MIN(L21,AI21),"-") -> - | BG21: =IF(COUNTIF(AX21:BF21,"<>-")=9,SUM(AX21:BF21),"-") -> - | BH21: =IF(AND(N21>0,AK21>0),MIN(N21,AK21),"-") -> - | BI21: =IF(AND(O21>0,AL21>0),MIN(O21,AL21),"-") -> - | BJ21: =IF(AND(P21>0,AM21>0),MIN(P21,AM21),"-") -> - | BK21: =IF(AND(Q21>0,AN21>0),MIN(Q21,AN21),"-") -> - | BL21: =IF(AND(R21>0,AO21>0),MIN(R21,AO21),"-") -> - | BM21: =IF(AND(S21>0,AP21>0),MIN(S21,AP21),"-") -> - | BN21: =IF(AND(T21>0,AQ21>0),MIN(T21,AQ21),"-") -> - | BO21: =IF(AND(U21>0,AR21>0),MIN(U21,AR21),"-") -> - | BP21: =IF(AND(V21>0,AS21>0),MIN(V21,AS21),"-") -> - | BQ21: =IF(COUNTIF(BH21:BP21,"<>-")=9,SUM(BH21:BP21),"-") -> - | BR21: =BG21 -> - | BS21: =IF(COUNTIF(BQ21:BR21,"<>-")=2,SUM(BQ21:BR21),"-") -> - | BT21: =IF(ISNUMBER(BS21),BS21-(C21*Rules!$P$9/100),"-") -> - | BU21: =RANK($BT21,$BT$5:$BT$106,1)+COUNTIF(BT$5:BT21,BT21)-1 -> #VALUE! | BV21: =RANK(BT21,$BT$5:$BT$215,1) -> #VALUE! | BW21: =B21 | BX21: =C21 -> - | BY21: =BT21 -> - | CC21: 17 | CD21: =VLOOKUP(CC21,$BU$5:BY$215,2,FALSE) -> #N/A | CE21: =VLOOKUP(CC21,$BU$5:BY$215,3,FALSE) -> #N/A | CF21: =VLOOKUP(CC21,$BU$5:BY$215,5,FALSE) -> #N/A | CL21: 1
A22: 18 | B22: ='A Div'!A22 & " " & 'A Div'!B22 | C22: ='A Div'!E22 -> - | M22: =IF(COUNTIF(D22:L22,"<>"&"")=9,SUM(D22:L22),"-") -> - | W22: =IF(COUNTIF(N22:V22,"<>"&"")=9,SUM(N22:V22),"-") -> - | X22: =IF(AND(ISNUMBER(M22),ISNUMBER(W22)),M22+W22,"-") -> - | Y22: =IF(ISNUMBER(X22),X22-C22,"-") -> - | AJ22: =IF(COUNTIF(AA22:AI22,"<>"&"")=9,SUM(AA22:AI22),"-") -> - | AT22: =IF(COUNTIF(AK22:AS22,"<>"&"")=9,SUM(AK22:AS22),"-") -> - | AU22: =IF(AND(ISNUMBER(AJ22),ISNUMBER(AT22)),AJ22+AT22,"-") -> - | AV22: =IF(ISNUMBER(AU22),AU22-C22,"-") -> - | AX22: =IF(AND(D22>0,AA22>0),MIN(D22,AA22),"-") -> - | AY22: =IF(AND(E22>0,AB22>0),MIN(E22,AB22),"-") -> - | AZ22: =IF(AND(F22>0,AC22>0),MIN(F22,AC22),"-") -> - | BA22: =IF(AND(G22>0,AD22>0),MIN(G22,AD22),"-") -> - | BB22: =IF(AND(H22>0,AE22>0),MIN(H22,AE22),"-") -> - | BC22: =IF(AND(I22>0,AF22>0),MIN(I22,AF22),"-") -> - | BD22: =IF(AND(J22>0,AG22>0),MIN(J22,AG22),"-") -> - | BE22: =IF(AND(K22>0,AH22>0),MIN(K22,AH22),"-") -> - | BF22: =IF(AND(L22>0,AI22>0),MIN(L22,AI22),"-") -> - | BG22: =IF(COUNTIF(AX22:BF22,"<>-")=9,SUM(AX22:BF22),"-") -> - | BH22: =IF(AND(N22>0,AK22>0),MIN(N22,AK22),"-") -> - | BI22: =IF(AND(O22>0,AL22>0),MIN(O22,AL22),"-") -> - | BJ22: =IF(AND(P22>0,AM22>0),MIN(P22,AM22),"-") -> - | BK22: =IF(AND(Q22>0,AN22>0),MIN(Q22,AN22),"-") -> - | BL22: =IF(AND(R22>0,AO22>0),MIN(R22,AO22),"-") -> - | BM22: =IF(AND(S22>0,AP22>0),MIN(S22,AP22),"-") -> - | BN22: =IF(AND(T22>0,AQ22>0),MIN(T22,AQ22),"-") -> - | BO22: =IF(AND(U22>0,AR22>0),MIN(U22,AR22),"-") -> - | BP22: =IF(AND(V22>0,AS22>0),MIN(V22,AS22),"-") -> - | BQ22: =IF(COUNTIF(BH22:BP22,"<>-")=9,SUM(BH22:BP22),"-") -> - | BR22: =BG22 -> - | BS22: =IF(COUNTIF(BQ22:BR22,"<>-")=2,SUM(BQ22:BR22),"-") -> - | BT22: =IF(ISNUMBER(BS22),BS22-(C22*Rules!$P$9/100),"-") -> - | BU22: =RANK($BT22,$BT$5:$BT$106,1)+COUNTIF(BT$5:BT22,BT22)-1 -> #VALUE! | BV22: =RANK(BT22,$BT$5:$BT$215,1) -> #VALUE! | BW22: =B22 | BX22: =C22 -> - | BY22: =BT22 -> - | CC22: 18 | CD22: =VLOOKUP(CC22,$BU$5:BY$215,2,FALSE) -> #N/A | CE22: =VLOOKUP(CC22,$BU$5:BY$215,3,FALSE) -> #N/A | CF22: =VLOOKUP(CC22,$BU$5:BY$215,5,FALSE) -> #N/A | CL22: 1
A23: 19 | B23: ='A Div'!A23 & " " & 'A Div'!B23 | C23: ='A Div'!E23 -> - | M23: =IF(COUNTIF(D23:L23,"<>"&"")=9,SUM(D23:L23),"-") -> - | W23: =IF(COUNTIF(N23:V23,"<>"&"")=9,SUM(N23:V23),"-") -> - | X23: =IF(AND(ISNUMBER(M23),ISNUMBER(W23)),M23+W23,"-") -> - | Y23: =IF(ISNUMBER(X23),X23-C23,"-") -> - | AJ23: =IF(COUNTIF(AA23:AI23,"<>"&"")=9,SUM(AA23:AI23),"-") -> - | AT23: =IF(COUNTIF(AK23:AS23,"<>"&"")=9,SUM(AK23:AS23),"-") -> - | AU23: =IF(AND(ISNUMBER(AJ23),ISNUMBER(AT23)),AJ23+AT23,"-") -> - | AV23: =IF(ISNUMBER(AU23),AU23-C23,"-") -> - | AX23: =IF(AND(D23>0,AA23>0),MIN(D23,AA23),"-") -> - | AY23: =IF(AND(E23>0,AB23>0),MIN(E23,AB23),"-") -> - | AZ23: =IF(AND(F23>0,AC23>0),MIN(F23,AC23),"-") -> - | BA23: =IF(AND(G23>0,AD23>0),MIN(G23,AD23),"-") -> - | BB23: =IF(AND(H23>0,AE23>0),MIN(H23,AE23),"-") -> - | BC23: =IF(AND(I23>0,AF23>0),MIN(I23,AF23),"-") -> - | BD23: =IF(AND(J23>0,AG23>0),MIN(J23,AG23),"-") -> - | BE23: =IF(AND(K23>0,AH23>0),MIN(K23,AH23),"-") -> - | BF23: =IF(AND(L23>0,AI23>0),MIN(L23,AI23),"-") -> - | BG23: =IF(COUNTIF(AX23:BF23,"<>-")=9,SUM(AX23:BF23),"-") -> - | BH23: =IF(AND(N23>0,AK23>0),MIN(N23,AK23),"-") -> - | BI23: =IF(AND(O23>0,AL23>0),MIN(O23,AL23),"-") -> - | BJ23: =IF(AND(P23>0,AM23>0),MIN(P23,AM23),"-") -> - | BK23: =IF(AND(Q23>0,AN23>0),MIN(Q23,AN23),"-") -> - | BL23: =IF(AND(R23>0,AO23>0),MIN(R23,AO23),"-") -> - | BM23: =IF(AND(S23>0,AP23>0),MIN(S23,AP23),"-") -> - | BN23: =IF(AND(T23>0,AQ23>0),MIN(T23,AQ23),"-") -> - | BO23: =IF(AND(U23>0,AR23>0),MIN(U23,AR23),"-") -> - | BP23: =IF(AND(V23>0,AS23>0),MIN(V23,AS23),"-") -> - | BQ23: =IF(COUNTIF(BH23:BP23,"<>-")=9,SUM(BH23:BP23),"-") -> - | BR23: =BG23 -> - | BS23: =IF(COUNTIF(BQ23:BR23,"<>-")=2,SUM(BQ23:BR23),"-") -> - | BT23: =IF(ISNUMBER(BS23),BS23-(C23*Rules!$P$9/100),"-") -> - | BU23: =RANK($BT23,$BT$5:$BT$106,1)+COUNTIF(BT$5:BT23,BT23)-1 -> #VALUE! | BV23: =RANK(BT23,$BT$5:$BT$215,1) -> #VALUE! | BW23: =B23 | BX23: =C23 -> - | BY23: =BT23 -> - | CC23: 19 | CD23: =VLOOKUP(CC23,$BU$5:BY$215,2,FALSE) -> #N/A | CE23: =VLOOKUP(CC23,$BU$5:BY$215,3,FALSE) -> #N/A | CF23: =VLOOKUP(CC23,$BU$5:BY$215,5,FALSE) -> #N/A | CL23: 1
A24: 20 | B24: ='A Div'!A24 & " " & 'A Div'!B24 | C24: ='A Div'!E24 -> - | M24: =IF(COUNTIF(D24:L24,"<>"&"")=9,SUM(D24:L24),"-") -> - | W24: =IF(COUNTIF(N24:V24,"<>"&"")=9,SUM(N24:V24),"-") -> - | X24: =IF(AND(ISNUMBER(M24),ISNUMBER(W24)),M24+W24,"-") -> - | Y24: =IF(ISNUMBER(X24),X24-C24,"-") -> - | AJ24: =IF(COUNTIF(AA24:AI24,"<>"&"")=9,SUM(AA24:AI24),"-") -> - | AT24: =IF(COUNTIF(AK24:AS24,"<>"&"")=9,SUM(AK24:AS24),"-") -> - | AU24: =IF(AND(ISNUMBER(AJ24),ISNUMBER(AT24)),AJ24+AT24,"-") -> - | AV24: =IF(ISNUMBER(AU24),AU24-C24,"-") -> - | AX24: =IF(AND(D24>0,AA24>0),MIN(D24,AA24),"-") -> - | AY24: =IF(AND(E24>0,AB24>0),MIN(E24,AB24),"-") -> - | AZ24: =IF(AND(F24>0,AC24>0),MIN(F24,AC24),"-") -> - | BA24: =IF(AND(G24>0,AD24>0),MIN(G24,AD24),"-") -> - | BB24: =IF(AND(H24>0,AE24>0),MIN(H24,AE24),"-") -> - | BC24: =IF(AND(I24>0,AF24>0),MIN(I24,AF24),"-") -> - | BD24: =IF(AND(J24>0,AG24>0),MIN(J24,AG24),"-") -> - | BE24: =IF(AND(K24>0,AH24>0),MIN(K24,AH24),"-") -> - | BF24: =IF(AND(L24>0,AI24>0),MIN(L24,AI24),"-") -> - | BG24: =IF(COUNTIF(AX24:BF24,"<>-")=9,SUM(AX24:BF24),"-") -> - | BH24: =IF(AND(N24>0,AK24>0),MIN(N24,AK24),"-") -> - | BI24: =IF(AND(O24>0,AL24>0),MIN(O24,AL24),"-") -> - | BJ24: =IF(AND(P24>0,AM24>0),MIN(P24,AM24),"-") -> - | BK24: =IF(AND(Q24>0,AN24>0),MIN(Q24,AN24),"-") -> - | BL24: =IF(AND(R24>0,AO24>0),MIN(R24,AO24),"-") -> - | BM24: =IF(AND(S24>0,AP24>0),MIN(S24,AP24),"-") -> - | BN24: =IF(AND(T24>0,AQ24>0),MIN(T24,AQ24),"-") -> - | BO24: =IF(AND(U24>0,AR24>0),MIN(U24,AR24),"-") -> - | BP24: =IF(AND(V24>0,AS24>0),MIN(V24,AS24),"-") -> - | BQ24: =IF(COUNTIF(BH24:BP24,"<>-")=9,SUM(BH24:BP24),"-") -> - | BR24: =BG24 -> - | BS24: =IF(COUNTIF(BQ24:BR24,"<>-")=2,SUM(BQ24:BR24),"-") -> - | BT24: =IF(ISNUMBER(BS24),BS24-(C24*Rules!$P$9/100),"-") -> - | BU24: =RANK($BT24,$BT$5:$BT$106,1)+COUNTIF(BT$5:BT24,BT24)-1 -> #VALUE! | BV24: =RANK(BT24,$BT$5:$BT$215,1) -> #VALUE! | BW24: =B24 | BX24: =C24 -> - | BY24: =BT24 -> - | CC24: 20 | CD24: =VLOOKUP(CC24,$BU$5:BY$215,2,FALSE) -> #N/A | CE24: =VLOOKUP(CC24,$BU$5:BY$215,3,FALSE) -> #N/A | CF24: =VLOOKUP(CC24,$BU$5:BY$215,5,FALSE) -> #N/A | CL24: 1
A25: 21 | B25: ='A Div'!A25 & " " & 'A Div'!B25 | C25: ='A Div'!E25 -> - | M25: =IF(COUNTIF(D25:L25,"<>"&"")=9,SUM(D25:L25),"-") -> - | W25: =IF(COUNTIF(N25:V25,"<>"&"")=9,SUM(N25:V25),"-") -> - | X25: =IF(AND(ISNUMBER(M25),ISNUMBER(W25)),M25+W25,"-") -> - | Y25: =IF(ISNUMBER(X25),X25-C25,"-") -> - | AJ25: =IF(COUNTIF(AA25:AI25,"<>"&"")=9,SUM(AA25:AI25),"-") -> - | AT25: =IF(COUNTIF(AK25:AS25,"<>"&"")=9,SUM(AK25:AS25),"-") -> - | AU25: =IF(AND(ISNUMBER(AJ25),ISNUMBER(AT25)),AJ25+AT25,"-") -> - | AV25: =IF(ISNUMBER(AU25),AU25-C25,"-") -> - | AX25: =IF(AND(D25>0,AA25>0),MIN(D25,AA25),"-") -> - | AY25: =IF(AND(E25>0,AB25>0),MIN(E25,AB25),"-") -> - | AZ25: =IF(AND(F25>0,AC25>0),MIN(F25,AC25),"-") -> - | BA25: =IF(AND(G25>0,AD25>0),MIN(G25,AD25),"-") -> - | BB25: =IF(AND(H25>0,AE25>0),MIN(H25,AE25),"-") -> - | BC25: =IF(AND(I25>0,AF25>0),MIN(I25,AF25),"-") -> - | BD25: =IF(AND(J25>0,AG25>0),MIN(J25,AG25),"-") -> - | BE25: =IF(AND(K25>0,AH25>0),MIN(K25,AH25),"-") -> - | BF25: =IF(AND(L25>0,AI25>0),MIN(L25,AI25),"-") -> - | BG25: =IF(COUNTIF(AX25:BF25,"<>-")=9,SUM(AX25:BF25),"-") -> - | BH25: =IF(AND(N25>0,AK25>0),MIN(N25,AK25),"-") -> - | BI25: =IF(AND(O25>0,AL25>0),MIN(O25,AL25),"-") -> - | BJ25: =IF(AND(P25>0,AM25>0),MIN(P25,AM25),"-") -> - | BK25: =IF(AND(Q25>0,AN25>0),MIN(Q25,AN25),"-") -> - | BL25: =IF(AND(R25>0,AO25>0),MIN(R25,AO25),"-") -> - | BM25: =IF(AND(S25>0,AP25>0),MIN(S25,AP25),"-") -> - | BN25: =IF(AND(T25>0,AQ25>0),MIN(T25,AQ25),"-") -> - | BO25: =IF(AND(U25>0,AR25>0),MIN(U25,AR25),"-") -> - | BP25: =IF(AND(V25>0,AS25>0),MIN(V25,AS25),"-") -> - | BQ25: =IF(COUNTIF(BH25:BP25,"<>-")=9,SUM(BH25:BP25),"-") -> - | BR25: =BG25 -> - | BS25: =IF(COUNTIF(BQ25:BR25,"<>-")=2,SUM(BQ25:BR25),"-") -> - | BT25: =IF(ISNUMBER(BS25),BS25-(C25*Rules!$P$9/100),"-") -> - | BU25: =RANK($BT25,$BT$5:$BT$106,1)+COUNTIF(BT$5:BT25,BT25)-1 -> #VALUE! | BV25: =RANK(BT25,$BT$5:$BT$215,1) -> #VALUE! | BW25: =B25 | BX25: =C25 -> - | BY25: =BT25 -> - | CC25: 21 | CD25: =VLOOKUP(CC25,$BU$5:BY$215,2,FALSE) -> #N/A | CE25: =VLOOKUP(CC25,$BU$5:BY$215,3,FALSE) -> #N/A | CF25: =VLOOKUP(CC25,$BU$5:BY$215,5,FALSE) -> #N/A | CL25: 1
A26: 22 | B26: ='A Div'!A26 & " " & 'A Div'!B26 | C26: ='A Div'!E26 -> - | M26: =IF(COUNTIF(D26:L26,"<>"&"")=9,SUM(D26:L26),"-") -> - | W26: =IF(COUNTIF(N26:V26,"<>"&"")=9,SUM(N26:V26),"-") -> - | X26: =IF(AND(ISNUMBER(M26),ISNUMBER(W26)),M26+W26,"-") -> - | Y26: =IF(ISNUMBER(X26),X26-C26,"-") -> - | AJ26: =IF(COUNTIF(AA26:AI26,"<>"&"")=9,SUM(AA26:AI26),"-") -> - | AT26: =IF(COUNTIF(AK26:AS26,"<>"&"")=9,SUM(AK26:AS26),"-") -> - | AU26: =IF(AND(ISNUMBER(AJ26),ISNUMBER(AT26)),AJ26+AT26,"-") -> - | AV26: =IF(ISNUMBER(AU26),AU26-C26,"-") -> - | AX26: =IF(AND(D26>0,AA26>0),MIN(D26,AA26),"-") -> - | AY26: =IF(AND(E26>0,AB26>0),MIN(E26,AB26),"-") -> - | AZ26: =IF(AND(F26>0,AC26>0),MIN(F26,AC26),"-") -> - | BA26: =IF(AND(G26>0,AD26>0),MIN(G26,AD26),"-") -> - | BB26: =IF(AND(H26>0,AE26>0),MIN(H26,AE26),"-") -> - | BC26: =IF(AND(I26>0,AF26>0),MIN(I26,AF26),"-") -> - | BD26: =IF(AND(J26>0,AG26>0),MIN(J26,AG26),"-") -> - | BE26: =IF(AND(K26>0,AH26>0),MIN(K26,AH26),"-") -> - | BF26: =IF(AND(L26>0,AI26>0),MIN(L26,AI26),"-") -> - | BG26: =IF(COUNTIF(AX26:BF26,"<>-")=9,SUM(AX26:BF26),"-") -> - | BH26: =IF(AND(N26>0,AK26>0),MIN(N26,AK26),"-") -> - | BI26: =IF(AND(O26>0,AL26>0),MIN(O26,AL26),"-") -> - | BJ26: =IF(AND(P26>0,AM26>0),MIN(P26,AM26),"-") -> - | BK26: =IF(AND(Q26>0,AN26>0),MIN(Q26,AN26),"-") -> - | BL26: =IF(AND(R26>0,AO26>0),MIN(R26,AO26),"-") -> - | BM26: =IF(AND(S26>0,AP26>0),MIN(S26,AP26),"-") -> - | BN26: =IF(AND(T26>0,AQ26>0),MIN(T26,AQ26),"-") -> - | BO26: =IF(AND(U26>0,AR26>0),MIN(U26,AR26),"-") -> - | BP26: =IF(AND(V26>0,AS26>0),MIN(V26,AS26),"-") -> - | BQ26: =IF(COUNTIF(BH26:BP26,"<>-")=9,SUM(BH26:BP26),"-") -> - | BR26: =BG26 -> - | BS26: =IF(COUNTIF(BQ26:BR26,"<>-")=2,SUM(BQ26:BR26),"-") -> - | BT26: =IF(ISNUMBER(BS26),BS26-(C26*Rules!$P$9/100),"-") -> - | BU26: =RANK($BT26,$BT$5:$BT$106,1)+COUNTIF(BT$5:BT26,BT26)-1 -> #VALUE! | BV26: =RANK(BT26,$BT$5:$BT$215,1) -> #VALUE! | BW26: =B26 | BX26: =C26 -> - | BY26: =BT26 -> - | CC26: 22 | CD26: =VLOOKUP(CC26,$BU$5:BY$215,2,FALSE) -> #N/A | CE26: =VLOOKUP(CC26,$BU$5:BY$215,3,FALSE) -> #N/A | CF26: =VLOOKUP(CC26,$BU$5:BY$215,5,FALSE) -> #N/A | CL26: 1
A27: 23 | B27: ='A Div'!A27 & " " & 'A Div'!B27 | C27: ='A Div'!E27 -> - | M27: =IF(COUNTIF(D27:L27,"<>"&"")=9,SUM(D27:L27),"-") -> - | W27: =IF(COUNTIF(N27:V27,"<>"&"")=9,SUM(N27:V27),"-") -> - | X27: =IF(AND(ISNUMBER(M27),ISNUMBER(W27)),M27+W27,"-") -> - | Y27: =IF(ISNUMBER(X27),X27-C27,"-") -> - | AJ27: =IF(COUNTIF(AA27:AI27,"<>"&"")=9,SUM(AA27:AI27),"-") -> - | AT27: =IF(COUNTIF(AK27:AS27,"<>"&"")=9,SUM(AK27:AS27),"-") -> - | AU27: =IF(AND(ISNUMBER(AJ27),ISNUMBER(AT27)),AJ27+AT27,"-") -> - | AV27: =IF(ISNUMBER(AU27),AU27-C27,"-") -> - | AX27: =IF(AND(D27>0,AA27>0),MIN(D27,AA27),"-") -> - | AY27: =IF(AND(E27>0,AB27>0),MIN(E27,AB27),"-") -> - | AZ27: =IF(AND(F27>0,AC27>0),MIN(F27,AC27),"-") -> - | BA27: =IF(AND(G27>0,AD27>0),MIN(G27,AD27),"-") -> - | BB27: =IF(AND(H27>0,AE27>0),MIN(H27,AE27),"-") -> - | BC27: =IF(AND(I27>0,AF27>0),MIN(I27,AF27),"-") -> - | BD27: =IF(AND(J27>0,AG27>0),MIN(J27,AG27),"-") -> - | BE27: =IF(AND(K27>0,AH27>0),MIN(K27,AH27),"-") -> - | BF27: =IF(AND(L27>0,AI27>0),MIN(L27,AI27),"-") -> - | BG27: =IF(COUNTIF(AX27:BF27,"<>-")=9,SUM(AX27:BF27),"-") -> - | BH27: =IF(AND(N27>0,AK27>0),MIN(N27,AK27),"-") -> - | BI27: =IF(AND(O27>0,AL27>0),MIN(O27,AL27),"-") -> - | BJ27: =IF(AND(P27>0,AM27>0),MIN(P27,AM27),"-") -> - | BK27: =IF(AND(Q27>0,AN27>0),MIN(Q27,AN27),"-") -> - | BL27: =IF(AND(R27>0,AO27>0),MIN(R27,AO27),"-") -> - | BM27: =IF(AND(S27>0,AP27>0),MIN(S27,AP27),"-") -> - | BN27: =IF(AND(T27>0,AQ27>0),MIN(T27,AQ27),"-") -> - | BO27: =IF(AND(U27>0,AR27>0),MIN(U27,AR27),"-") -> - | BP27: =IF(AND(V27>0,AS27>0),MIN(V27,AS27),"-") -> - | BQ27: =IF(COUNTIF(BH27:BP27,"<>-")=9,SUM(BH27:BP27),"-") -> - | BR27: =BG27 -> - | BS27: =IF(COUNTIF(BQ27:BR27,"<>-")=2,SUM(BQ27:BR27),"-") -> - | BT27: =IF(ISNUMBER(BS27),BS27-(C27*Rules!$P$9/100),"-") -> - | BU27: =RANK($BT27,$BT$5:$BT$106,1)+COUNTIF(BT$5:BT27,BT27)-1 -> #VALUE! | BV27: =RANK(BT27,$BT$5:$BT$215,1) -> #VALUE! | BW27: =B27 | BX27: =C27 -> - | BY27: =BT27 -> - | CC27: 23 | CD27: =VLOOKUP(CC27,$BU$5:BY$215,2,FALSE) -> #N/A | CE27: =VLOOKUP(CC27,$BU$5:BY$215,3,FALSE) -> #N/A | CF27: =VLOOKUP(CC27,$BU$5:BY$215,5,FALSE) -> #N/A | CL27: 1
A28: 24 | B28: ='A Div'!A28 & " " & 'A Div'!B28 | C28: ='A Div'!E28 -> - | M28: =IF(COUNTIF(D28:L28,"<>"&"")=9,SUM(D28:L28),"-") -> - | W28: =IF(COUNTIF(N28:V28,"<>"&"")=9,SUM(N28:V28),"-") -> - | X28: =IF(AND(ISNUMBER(M28),ISNUMBER(W28)),M28+W28,"-") -> - | Y28: =IF(ISNUMBER(X28),X28-C28,"-") -> - | AJ28: =IF(COUNTIF(AA28:AI28,"<>"&"")=9,SUM(AA28:AI28),"-") -> - | AT28: =IF(COUNTIF(AK28:AS28,"<>"&"")=9,SUM(AK28:AS28),"-") -> - | AU28: =IF(AND(ISNUMBER(AJ28),ISNUMBER(AT28)),AJ28+AT28,"-") -> - | AV28: =IF(ISNUMBER(AU28),AU28-C28,"-") -> - | AX28: =IF(AND(D28>0,AA28>0),MIN(D28,AA28),"-") -> - | AY28: =IF(AND(E28>0,AB28>0),MIN(E28,AB28),"-") -> - | AZ28: =IF(AND(F28>0,AC28>0),MIN(F28,AC28),"-") -> - | BA28: =IF(AND(G28>0,AD28>0),MIN(G28,AD28),"-") -> - | BB28: =IF(AND(H28>0,AE28>0),MIN(H28,AE28),"-") -> - | BC28: =IF(AND(I28>0,AF28>0),MIN(I28,AF28),"-") -> - | BD28: =IF(AND(J28>0,AG28>0),MIN(J28,AG28),"-") -> - | BE28: =IF(AND(K28>0,AH28>0),MIN(K28,AH28),"-") -> - | BF28: =IF(AND(L28>0,AI28>0),MIN(L28,AI28),"-") -> - | BG28: =IF(COUNTIF(AX28:BF28,"<>-")=9,SUM(AX28:BF28),"-") -> - | BH28: =IF(AND(N28>0,AK28>0),MIN(N28,AK28),"-") -> - | BI28: =IF(AND(O28>0,AL28>0),MIN(O28,AL28),"-") -> - | BJ28: =IF(AND(P28>0,AM28>0),MIN(P28,AM28),"-") -> - | BK28: =IF(AND(Q28>0,AN28>0),MIN(Q28,AN28),"-") -> - | BL28: =IF(AND(R28>0,AO28>0),MIN(R28,AO28),"-") -> - | BM28: =IF(AND(S28>0,AP28>0),MIN(S28,AP28),"-") -> - | BN28: =IF(AND(T28>0,AQ28>0),MIN(T28,AQ28),"-") -> - | BO28: =IF(AND(U28>0,AR28>0),MIN(U28,AR28),"-") -> - | BP28: =IF(AND(V28>0,AS28>0),MIN(V28,AS28),"-") -> - | BQ28: =IF(COUNTIF(BH28:BP28,"<>-")=9,SUM(BH28:BP28),"-") -> - | BR28: =BG28 -> - | BS28: =IF(COUNTIF(BQ28:BR28,"<>-")=2,SUM(BQ28:BR28),"-") -> - | BT28: =IF(ISNUMBER(BS28),BS28-(C28*Rules!$P$9/100),"-") -> - | BU28: =RANK($BT28,$BT$5:$BT$106,1)+COUNTIF(BT$5:BT28,BT28)-1 -> #VALUE! | BV28: =RANK(BT28,$BT$5:$BT$215,1) -> #VALUE! | BW28: =B28 | BX28: =C28 -> - | BY28: =BT28 -> - | CC28: 24 | CD28: =VLOOKUP(CC28,$BU$5:BY$215,2,FALSE) -> #N/A | CE28: =VLOOKUP(CC28,$BU$5:BY$215,3,FALSE) -> #N/A | CF28: =VLOOKUP(CC28,$BU$5:BY$215,5,FALSE) -> #N/A | CL28: 1
A29: 25 | B29: ='A Div'!A29 & " " & 'A Div'!B29 | C29: ='A Div'!E29 -> - | M29: =IF(COUNTIF(D29:L29,"<>"&"")=9,SUM(D29:L29),"-") -> - | W29: =IF(COUNTIF(N29:V29,"<>"&"")=9,SUM(N29:V29),"-") -> - | X29: =IF(AND(ISNUMBER(M29),ISNUMBER(W29)),M29+W29,"-") -> - | Y29: =IF(ISNUMBER(X29),X29-C29,"-") -> - | AJ29: =IF(COUNTIF(AA29:AI29,"<>"&"")=9,SUM(AA29:AI29),"-") -> - | AT29: =IF(COUNTIF(AK29:AS29,"<>"&"")=9,SUM(AK29:AS29),"-") -> - | AU29: =IF(AND(ISNUMBER(AJ29),ISNUMBER(AT29)),AJ29+AT29,"-") -> - | AV29: =IF(ISNUMBER(AU29),AU29-C29,"-") -> - | AX29: =IF(AND(D29>0,AA29>0),MIN(D29,AA29),"-") -> - | AY29: =IF(AND(E29>0,AB29>0),MIN(E29,AB29),"-") -> - | AZ29: =IF(AND(F29>0,AC29>0),MIN(F29,AC29),"-") -> - | BA29: =IF(AND(G29>0,AD29>0),MIN(G29,AD29),"-") -> - | BB29: =IF(AND(H29>0,AE29>0),MIN(H29,AE29),"-") -> - | BC29: =IF(AND(I29>0,AF29>0),MIN(I29,AF29),"-") -> - | BD29: =IF(AND(J29>0,AG29>0),MIN(J29,AG29),"-") -> - | BE29: =IF(AND(K29>0,AH29>0),MIN(K29,AH29),"-") -> - | BF29: =IF(AND(L29>0,AI29>0),MIN(L29,AI29),"-") -> - | BG29: =IF(COUNTIF(AX29:BF29,"<>-")=9,SUM(AX29:BF29),"-") -> - | BH29: =IF(AND(N29>0,AK29>0),MIN(N29,AK29),"-") -> - | BI29: =IF(AND(O29>0,AL29>0),MIN(O29,AL29),"-") -> - | BJ29: =IF(AND(P29>0,AM29>0),MIN(P29,AM29),"-") -> - | BK29: =IF(AND(Q29>0,AN29>0),MIN(Q29,AN29),"-") -> - | BL29: =IF(AND(R29>0,AO29>0),MIN(R29,AO29),"-") -> - | BM29: =IF(AND(S29>0,AP29>0),MIN(S29,AP29),"-") -> - | BN29: =IF(AND(T29>0,AQ29>0),MIN(T29,AQ29),"-") -> - | BO29: =IF(AND(U29>0,AR29>0),MIN(U29,AR29),"-") -> - | BP29: =IF(AND(V29>0,AS29>0),MIN(V29,AS29),"-") -> - | BQ29: =IF(COUNTIF(BH29:BP29,"<>-")=9,SUM(BH29:BP29),"-") -> - | BR29: =BG29 -> - | BS29: =IF(COUNTIF(BQ29:BR29,"<>-")=2,SUM(BQ29:BR29),"-") -> - | BT29: =IF(ISNUMBER(BS29),BS29-(C29*Rules!$P$9/100),"-") -> - | BU29: =RANK($BT29,$BT$5:$BT$106,1)+COUNTIF(BT$5:BT29,BT29)-1 -> #VALUE! | BV29: =RANK(BT29,$BT$5:$BT$215,1) -> #VALUE! | BW29: =B29 | BX29: =C29 -> - | BY29: =BT29 -> - | CC29: 25 | CD29: =VLOOKUP(CC29,$BU$5:BY$215,2,FALSE) -> #N/A | CE29: =VLOOKUP(CC29,$BU$5:BY$215,3,FALSE) -> #N/A | CF29: =VLOOKUP(CC29,$BU$5:BY$215,5,FALSE) -> #N/A | CL29: 1
